Workbook

Sheet الفهرس
A1: مشروع تحليل مبيعات — شركة الأفق للتجزئة
A2: ↩ الفهرس | B2: تحليل شامل لـ 1,500 عملية بيع خلال 12 شهراً — بيانات وهمية بالكامل لأغراض التدريب والعرض
A4: عدد السجلات | B4: إجمالي الإيراد (ريال) | C4: إجمالي الربح (ريال) | D4: درجة جودة البيانات
A5: =ROWS(d_Order) -> 1500 | B5: =SUM(d_Rev) -> 2136589.5 | C5: =SUM(d_Profit) -> 715514.5 | D5: ='جودة البيانات'!B3 -> 1
A7: فهرس الأوراق (اضغط على الاسم للانتقال)
A8: # | B8: الورقة | C8: ماذا تجد فيها؟ | D8: أبرز مهارات Excel
A9: 1 | B9: لوحة المؤشرات | C9: لوحة تفاعلية: 6 مؤشرات رئيسية و4 رسوم تتغير بفلاتر المنطقة/الفئة/القناة | D9: قوائم منسدلة، SUMIFS/COUNTIFS بمعايير متعددة، بطاقات KPI، رسوم مركّبة
A10: 2 | B10: الرؤى والتوصيات | C10: 12 نتيجة و6 توصيات تُكتب تلقائياً من الأرقام | D10: نصوص ديناميكية: TEXT، INDEX/MATCH، التجميع بين الأوراق
A11: 3 | B11: تحليل الزمن | C11: النمو الشهري، المتوسط المتحرك، مؤشر الموسمية، الأرباع، أيام الأسبوع | D11: EDATE، RANK، SUMPRODUCT+WEEKDAY، Icon Sets، Color Scales، Data Bars
A12: 4 | B12: الفئات والمناطق | C12: الفئات والمناطق والقنوات + مصفوفة الإيراد وخريطة حرارية للهامش | D12: جداول محورية بالصيغ، AVERAGEIFS، رسم مُكدّس ودائري
A13: 5 | B13: تحليل المنتجات | C13: ترتيب المنتجات، تصنيف الأداء، باريتو ABC، المبعثر | D13: RANK مع كسر التعادل، INDEX/MATCH، رسم باريتو بمحور ثانوي، Scatter
A14: 6 | B14: تحليل العملاء | C14: تقسيم RFM لـ 200 عميل، أفضل 10 عملاء، حسب النوع | D14: QUARTILE، IF المتداخلة، SUMPRODUCT(MAX)، فلتر تلقائي
A15: 7 | B15: الموظفون | C15: أهداف الموظفين، التحقيق، شرائح الحوافز والعمولات | D15: VLOOKUP التقريبي، مدخلات قابلة للتعديل، رسوم أعمدة
A16: 8 | B16: الأهداف | C16: خطة شهرية بأوزان موسمية، تحقيق تراكمي، أهداف إقليمية | D16: إشارات المرور، حالات نصية ملوّنة، تراكمي
A17: 9 | B17: الإحصاء والتنبؤ | C17: إحصاء وصفي، مدرج تكراري، ارتباط وانحدار، تنبؤ 3 أشهر | D17: STDEV، SKEW، KURT، CONFIDENCE، CORREL، SLOPE، FORECAST، STEYX
A18: 10 | B18: السيناريوهات | C18: 4 سيناريوهات، جدول حساسية، أثر السيناريو على الفئات | D18: What-If، INDEX/MATCH للسيناريو المختار، مقياس لوني بنقطة وسط
A19: 11 | B19: جودة البيانات | C19: 12 فحصاً للجودة + تسوية الإيراد بين 8 أوراق | D19: COUNTIF، SUMPRODUCT، ISNA+MATCH، حالات سليم/مراجعة
A20: 12 | B20: البيانات | C20: 1,500 سطر مبيعات (جدول Excel) بأعمدة محسوبة | D20: جدول tblSales، أسماء معرّفة، تحقق من البيانات، تجميد، تلوين المرتجعات
... A22: 14 | B22: العملاء | C22: سجل 200 عميل بالنوع والمدينة والمنطقة | D22: فلتر تلقائي، أسماء معرّفة
A25: دليل الألوان
A26: 1,250 | B26: خط أزرق + خلفية صفراء = مدخل/افتراض قابل للتعديل
A27: 1,250 | B27: خط أسود = صيغة محسوبة (لا تكتب فوقها)
A28: سليم | B28: أخضر = تحقق/نتيجة جيدة
A29: مراجعة | B29: أحمر/برتقالي = تحتاج انتباهاً
A31: كيف تستخدم المشروع؟
A32: 1) ابدأ من «لوحة المؤشرات» وغيّر الفلاتر الصفراء لترى الأرقام والرسوم تتبدل فوراً.
A33: 2) اقرأ «الرؤى والتوصيات» ثم انتقل لورقة التحليل التي تهمّك للتفاصيل.
A34: 3) جرّب «السيناريوهات»: عدّل التغيّر في السعر والحجم والتكلفة واختر السيناريو من القائمة.
A35: 4) أضف أسطراً جديدة في جدول «البيانات» (الصيغ تمتد تلقائياً)، وعدّل الأسماء المعرّفة إن لزم.
A36: 5) راجع «جودة البيانات» دائماً للتأكد من تطابق الإجماليات.
A38: ملاحظات
A39: • كل البيانات وهمية (أسماء، أرقام، أهداف، عمولات) وولّدت بخوارزمية عشوائية ثابتة؛ لا تمثل أي شركة حقيقية.
A40: • الأهداف والمصروفات التشغيلية افتراضات للعرض وموثّقة بتعليقات على خلاياها (الخلايا الصفراء).
A41: • لا تستخدم المشروع دوال حديثة (XLOOKUP/FILTER) ليعمل على كل إصدارات Excel 2010 فما فوق.

Sheet لوحة المؤشرات
A1: ↩ | B1: لوحة مؤشرات الأداء — شركة الأفق للتجزئة
B2: ="الفترة: "&TEXT(MIN(d_Date),"yyyy/mm/dd")&" ← "&TEXT(MAX(d_Date),"yyyy/mm/dd")&" | السجلات: "&TEXT(ROWS(d_Order),"#,##0")&" | لوحة تفاعلية: غيّر الفلاتر من الخلايا الصفراء" -> الفترة: 2025/10/01 ← 2026/09/30 | السجلات: 1,500 | لوحة تفاعلية: غيّر الفلاتر من الخلايا الصفراء
O3: معايير الفلاتر (آلي)
B4: المنطقة | C4: الكل | E4: الفئة | F4: الكل | I4: القناة | J4: الكل | O4: =IF($C$4="الكل","*",$C$4) -> * | P4: المنطقة
O5: =IF($F$4="الكل","*",$F$4) -> * | P5: الفئة
B6: الإيراد الصافي (ريال) | D6: الربح (ريال) | F6: الطلبات المكتملة | H6: الوحدات المباعة | J6: معدل المرتجعات | L6: تحقيق الهدف السنوي | O6: =IF($J$4="الكل","*",$J$4) -> * | P6: القناة
B7: =SUMIFS(d_Rev,d_Region,$O$4,d_Cat,$O$5,d_Channel,$O$6) -> 2136589.5 | D7: =SUMIFS(d_Profit,d_Region,$O$4,d_Cat,$O$5,d_Channel,$O$6) -> 715514.5 | F7: =COUNTIFS(d_Region,$O$4,d_Cat,$O$5,d_Channel,$O$6,d_Status,"مكتمل") -> 1434 | H7: =SUMIFS(d_Qty,d_Region,$O$4,d_Cat,$O$5,d_Channel,$O$6,d_Status,"مكتمل") -> 4146 | J7: =IFERROR(COUNTIFS(d_Region,$O$4,d_Cat,$O$5,d_Channel,$O$6,d_Status,"مرتجع")/COUNTIFS(d_Region,$O$4,d_Cat,$O$5,d_Channel,$O$6),0) -> 0.044 | L7: =IFERROR(SUM(d_Rev)/الأهداف!B4,0) -> 0.9624277
B8: ="حصة من الشركة: "&TEXT(IFERROR(B7/SUM(d_Rev),0),"0.0%") -> حصة من الشركة: 100.0% | D8: ="هامش الربح: "&TEXT(IFERROR(D7/B7,0),"0.0%") -> هامش الربح: 33.5% | F8: ="متوسط الطلب: "&TEXT(IFERROR(B7/F7,0),"#,##0")&" ريال" -> متوسط الطلب: 1,490 ريال | H8: ="وحدات/طلب: "&TEXT(IFERROR(H7/F7,0),"0.0") -> وحدات/طلب: 2.9 | J8: ="عدد المرتجعات: "&COUNTIFS(d_Region,$O$4,d_Cat,$O$5,d_Channel,$O$6,d_Status,"مرتجع") -> عدد المرتجعات: 66 | L8: ="الهدف: "&TEXT(الأهداف!B4,"#,##0") -> الهدف: 2,220,000
B42: جداول مصدر الرسوم (تتأثر بالفلاتر أعلاه)
B43: بداية الفترة | C43: الشهر | D43: الإيراد | E43: الربح | G43: الفئة | H43: الإيراد | I43: الربح | K43: القناة | L43: الإيراد
B44: ='تحليل الزمن'!A5 -> 45931 | C44: =TEXT(B44,"yyyy-mm") -> 2025-10 | D44: =SUMIFS(d_Rev,d_Period,$B44,d_Region,$O$4,d_Cat,$O$5,d_Channel,$O$6) -> 186629.5 | E44: =SUMIFS(d_Profit,d_Period,$B44,d_Region,$O$4,d_Cat,$O$5,d_Channel,$O$6) -> 66799.5 | G44: إلكترونيات | H44: =SUMIFS(d_Rev,d_Cat,$G44,d_Region,$O$4,d_Channel,$O$6) -> 524652.5 | I44: =SUMIFS(d_Profit,d_Cat,$G44,d_Region,$O$4,d_Channel,$O$6) -> 123282.5 | K44: متجر | L44: =SUMIFS(d_Rev,d_Channel,$K44,d_Region,$O$4,d_Cat,$O$5) -> 844286.5
B45: ='تحليل الزمن'!A6 -> 45962 | C45: =TEXT(B45,"yyyy-mm") -> 2025-11 | D45: =SUMIFS(d_Rev,d_Period,$B45,d_Region,$O$4,d_Cat,$O$5,d_Channel,$O$6) -> 211433 | E45: =SUMIFS(d_Profit,d_Period,$B45,d_Region,$O$4,d_Cat,$O$5,d_Channel,$O$6) -> 65588 | G45: أجهزة منزلية | H45: =SUMIFS(d_Rev,d_Cat,$G45,d_Region,$O$4,d_Channel,$O$6) -> 260789 | I45: =SUMIFS(d_Profit,d_Cat,$G45,d_Region,$O$4,d_Channel,$O$6) -> 83319 | K45: أونلاين | L45: =SUMIFS(d_Rev,d_Channel,$K45,d_Region,$O$4,d_Cat,$O$5) -> 830453.5
B46: ='تحليل الزمن'!A7 -> 45992 | C46: =TEXT(B46,"yyyy-mm") -> 2025-12 | D46: =SUMIFS(d_Rev,d_Period,$B46,d_Region,$O$4,d_Cat,$O$5,d_Channel,$O$6) -> 183489.5 | E46: =SUMIFS(d_Profit,d_Period,$B46,d_Region,$O$4,d_Cat,$O$5,d_Channel,$O$6) -> 66759.5 | G46: أثاث | H46: =SUMIFS(d_Rev,d_Cat,$G46,d_Region,$O$4,d_Channel,$O$6) -> 583692.5 | I46: =SUMIFS(d_Profit,d_Cat,$G46,d_Region,$O$4,d_Channel,$O$6) -> 219682.5 | K46: جملة | L46: =SUMIFS(d_Rev,d_Channel,$K46,d_Region,$O$4,d_Cat,$O$5) -> 461849.5
B47: ='تحليل الزمن'!A8 -> 46023 | C47: =TEXT(B47,"yyyy-mm") -> 2026-01 | D47: =SUMIFS(d_Rev,d_Period,$B47,d_Region,$O$4,d_Cat,$O$5,d_Channel,$O$6) -> 168383.5 | E47: =SUMIFS(d_Profit,d_Period,$B47,d_Region,$O$4,d_Cat,$O$5,d_Channel,$O$6) -> 58283.5 | G47: مستلزمات مكتبية | H47: =SUMIFS(d_Rev,d_Cat,$G47,d_Region,$O$4,d_Channel,$O$6) -> 333618.5 | I47: =SUMIFS(d_Profit,d_Cat,$G47,d_Region,$O$4,d_Channel,$O$6) -> 107613.5
B48: ='تحليل الزمن'!A9 -> 46054 | C48: =TEXT(B48,"yyyy-mm") -> 2026-02 | D48: =SUMIFS(d_Rev,d_Period,$B48,d_Region,$O$4,d_Cat,$O$5,d_Channel,$O$6) -> 221778.5 | E48: =SUMIFS(d_Profit,d_Period,$B48,d_Region,$O$4,d_Cat,$O$5,d_Channel,$O$6) -> 77368.5 | G48: رياضة | H48: =SUMIFS(d_Rev,d_Cat,$G48,d_Region,$O$4,d_Channel,$O$6) -> 187066 | I48: =SUMIFS(d_Profit,d_Cat,$G48,d_Region,$O$4,d_Channel,$O$6) -> 64256 | K48: المنطقة | L48: الإيراد
B49: ='تحليل الزمن'!A10 -> 46082 | C49: =TEXT(B49,"yyyy-mm") -> 2026-03 | D49: =SUMIFS(d_Rev,d_Period,$B49,d_Region,$O$4,d_Cat,$O$5,d_Channel,$O$6) -> 157027.5 | E49: =SUMIFS(d_Profit,d_Period,$B49,d_Region,$O$4,d_Cat,$O$5,d_Channel,$O$6) -> 52987.5 | G49: عناية شخصية | H49: =SUMIFS(d_Rev,d_Cat,$G49,d_Region,$O$4,d_Channel,$O$6) -> 246771 | I49: =SUMIFS(d_Profit,d_Cat,$G49,d_Region,$O$4,d_Channel,$O$6) -> 117361 | K49: الوسطى | L49: =SUMIFS(d_Rev,d_Region,$K49,d_Cat,$O$5,d_Channel,$O$6) -> 692926.5
B50: ='تحليل الزمن'!A11 -> 46113 | C50: =TEXT(B50,"yyyy-mm") -> 2026-04 | D50: =SUMIFS(d_Rev,d_Period,$B50,d_Region,$O$4,d_Cat,$O$5,d_Channel,$O$6) -> 166026.5 | E50: =SUMIFS(d_Profit,d_Period,$B50,d_Region,$O$4,d_Cat,$O$5,d_Channel,$O$6) -> 51891.5 | K50: الغربية | L50: =SUMIFS(d_Rev,d_Region,$K50,d_Cat,$O$5,d_Channel,$O$6) -> 565303
B51: ='تحليل الزمن'!A12 -> 46143 | C51: =TEXT(B51,"yyyy-mm") -> 2026-05 | D51: =SUMIFS(d_Rev,d_Period,$B51,d_Region,$O$4,d_Cat,$O$5,d_Channel,$O$6) -> 204552.5 | E51: =SUMIFS(d_Profit,d_Period,$B51,d_Region,$O$4,d_Cat,$O$5,d_Channel,$O$6) -> 71347.5 | K51: الشرقية | L51: =SUMIFS(d_Rev,d_Region,$K51,d_Cat,$O$5,d_Channel,$O$6) -> 499447
B52: ='تحليل الزمن'!A13 -> 46174 | C52: =TEXT(B52,"yyyy-mm") -> 2026-06 | D52: =SUMIFS(d_Rev,d_Period,$B52,d_Region,$O$4,d_Cat,$O$5,d_Channel,$O$6) -> 165984 | E52: =SUMIFS(d_Profit,d_Period,$B52,d_Region,$O$4,d_Cat,$O$5,d_Channel,$O$6) -> 51139 | K52: الجنوبية | L52: =SUMIFS(d_Rev,d_Region,$K52,d_Cat,$O$5,d_Channel,$O$6) -> 378913
B53: ='تحليل الزمن'!A14 -> 46204 | C53: =TEXT(B53,"yyyy-mm") -> 2026-07 | D53: =SUMIFS(d_Rev,d_Period,$B53,d_Region,$O$4,d_Cat,$O$5,d_Channel,$O$6) -> 137862.5 | E53: =SUMIFS(d_Profit,d_Period,$B53,d_Region,$O$4,d_Cat,$O$5,d_Channel,$O$6) -> 47002.5
B54: ='تحليل الزمن'!A15 -> 46235 | C54: =TEXT(B54,"yyyy-mm") -> 2026-08 | D54: =SUMIFS(d_Rev,d_Period,$B54,d_Region,$O$4,d_Cat,$O$5,d_Channel,$O$6) -> 153928.5 | E54: =SUMIFS(d_Profit,d_Period,$B54,d_Region,$O$4,d_Cat,$O$5,d_Channel,$O$6) -> 49338.5
B55: ='تحليل الزمن'!A16 -> 46266 | C55: =TEXT(B55,"yyyy-mm") -> 2026-09 | D55: =SUMIFS(d_Rev,d_Period,$B55,d_Region,$O$4,d_Cat,$O$5,d_Channel,$O$6) -> 179494 | E55: =SUMIFS(d_Profit,d_Period,$B55,d_Region,$O$4,d_Cat,$O$5,d_Channel,$O$6) -> 57009

Sheet الرؤى والتوصيات
A1: الرؤى والتوصيات (نصوص ديناميكية)
A2: ↩ الفهرس | B2: كل جملة هنا صيغة حيّة؛ تتحدث تلقائياً عند تغيير البيانات أو الافتراضات
A4: أولاً: أبرز النتائج
A5: # | B5: النتيجة | C5: المصدر
A6: 1 | B6: ="أقوى الأشهر مبيعاً "&INDEX('تحليل الزمن'!B5:B16,MATCH(1,'تحليل الزمن'!K5:K16,0))&" بإيراد "&TEXT(MAX('تحليل الزمن'!C5:C16),"#,##0")&" ريال، وأضعفها "&INDEX('تحليل الزمن'!B5:B16,MATCH(12,'تحليل الزمن'!K5:K16,0))&" بإيراد "&TEXT(MIN('تحليل الزمن'!C5:C16),"#,##0")&" ريال؛ أي أن الذروة تعادل "&TEXT(MAX('تحليل الزمن'!C5:C16)/MIN('تحليل الزمن'!C5:C16),"0.0")&" أضعاف القاع." -> أقوى الأشهر مبيعاً فبراير 2026 بإيراد 221,779 ريال، وأضعفها يوليو 2026 بإيراد 137,863 ريال؛ أي أن الذروة تعادل 1.6 أضعاف القاع. | C6: تحليل الزمن
A7: 2 | B7: ="إجمالي الإيراد "&TEXT('تحليل الزمن'!C17,"#,##0")&" ريال بهامش ربح "&TEXT('تحليل الزمن'!E17,"0.0%")&"، ويتغيّر الاتجاه الخطي بمقدار "&TEXT('الإحصاء والتنبؤ'!B58,"+#,##0;-#,##0")&" ريال شهرياً (R² = "&TEXT('الإحصاء والتنبؤ'!B59,"0.00")&")." -> إجمالي الإيراد 2,136,590 ريال بهامش ربح 33.5%، ويتغيّر الاتجاه الخطي بمقدار -3,392 ريال شهرياً (R² = 0.24). | C7: الإحصاء والتنبؤ
A8: 3 | B8: ="فئة «"&INDEX('الفئات والمناطق'!A6:A11,MATCH(1,'الفئات والمناطق'!H6:H11,0))&"» تتصدر بحصة "&TEXT(MAX('الفئات والمناطق'!C6:C11),"0.0%")&" من الإيراد، بينما أعلى هامش ربح لدى فئة «"&INDEX('الفئات والمناطق'!A6:A11,MATCH(MAX('الفئات والمناطق'!E6:E11),'الفئات والمناطق'!E6:E11,0))&"» ("&TEXT(MAX('الفئات والمناطق'!E6:E11),"0.0%")&")." -> فئة «أثاث» تتصدر بحصة 27.3% من الإيراد، بينما أعلى هامش ربح لدى فئة «عناية شخصية» (47.6%). | C8: الفئات والمناطق
A9: 4 | B9: ="منطقة "&INDEX('الفئات والمناطق'!A16:A19,MATCH(1,'الفئات والمناطق'!H16:H19,0))&" الأولى بحصة "&TEXT(MAX('الفئات والمناطق'!C16:C19),"0.0%")&"، وأعلى المناطق ربحية "&INDEX('الفئات والمناطق'!A16:A19,MATCH(MAX('الفئات والمناطق'!E16:E19),'الفئات والمناطق'!E16:E19,0))&" بهامش "&TEXT(MAX('الفئات والمناطق'!E16:E19),"0.0%")&"." -> منطقة الوسطى الأولى بحصة 32.4%، وأعلى المناطق ربحية الجنوبية بهامش 34.6%. | C9: الفئات والمناطق
A10: 5 | B10: ="منتج «"&'تحليل المنتجات'!L6&"» الأعلى إيراداً ("&TEXT('تحليل المنتجات'!N6,"0.0%")&")؛ وتضم الفئة A "&'تحليل المنتجات'!L33&" من أصل "&ROWS('تحليل المنتجات'!L6:L29)&" منتجاً تحقق نحو "&TEXT('تحليل المنتجات'!N33,"0%")&" من الإيراد (تحليل باريتو)." -> منتج «مكتب عمل» الأعلى إيراداً (11.4%)؛ وتضم الفئة A 16 من أصل 24 منتجاً تحقق نحو 82% من الإيراد (تحليل باريتو). | C10: تحليل المنتجات
A11: 6 | B11: ="عدد المنتجات ذات الحجم المرتفع والهامش الأقل من المتوسط: "&COUNTIF('تحليل المنتجات'!I6:I29,"حجم بلا ربحية")&"، وعدد المنتجات ذات الهامش الجيد والمبيعات المحدودة (فرص نمو): "&COUNTIF('تحليل المنتجات'!I6:I29,"فرصة نمو")&"." -> عدد المنتجات ذات الحجم المرتفع والهامش الأقل من المتوسط: 4، وعدد المنتجات ذات الهامش الجيد والمبيعات المحدودة (فرص نمو): 11. | C11: تحليل المنتجات
A12: 7 | B12: ="أكبر 10 عملاء يمثلون "&TEXT(SUM('تحليل العملاء'!K6:K15),"0.0%")&" من الإيراد؛ وتضم شريحة الأبطال "&'تحليل العملاء'!B12&" عميلاً بحصة "&TEXT('تحليل العملاء'!D12,"0.0%")&"، مقابل "&'تحليل العملاء'!B16&" عميلاً نائماً." -> أكبر 10 عملاء يمثلون 30.4% من الإيراد؛ وتضم شريحة الأبطال 61 عميلاً بحصة 66.3%، مقابل 27 عميلاً نائماً. | C12: تحليل العملاء
A13: 8 | B13: ="معدل المرتجعات "&TEXT('الفئات والمناطق'!I12,"0.0%")&"، وأعلاها في قناة "&INDEX('الفئات والمناطق'!A24:A26,MATCH(MAX('الفئات والمناطق'!I24:I26),'الفئات والمناطق'!I24:I26,0))&" ("&TEXT(MAX('الفئات والمناطق'!I24:I26),"0.0%")&")." -> معدل المرتجعات 4.4%، وأعلاها في قناة أونلاين (6.5%). | C13: الفئات والمناطق
A14: 9 | B14: ="ارتباط الخصم بهامش الربح "&TEXT('الإحصاء والتنبؤ'!B30,"0.00")&" — "&'الإحصاء والتنبؤ'!C30&"؛ كل 10 نقاط خصم إضافية تقلّص الهامش بنحو "&TEXT(-'الإحصاء والتنبؤ'!B31*10,"0.0")&" نقطة مئوية." -> ارتباط الخصم بهامش الربح -0.41 — متوسط (عكسي)؛ كل 10 نقاط خصم إضافية تقلّص الهامش بنحو 7.3 نقطة مئوية. | C14: الإحصاء والتنبؤ
A15: 10 | B15: ="تحقق الهدف السنوي بنسبة "&TEXT(الأهداف!G21,"0.0%")&"، وحقق "&COUNTIF(الأهداف!H9:H20,"تحقق")&" أشهر من 12 هدفها؛ وأعلى المناطق تحقيقاً "&INDEX(الأهداف!A26:A29,MATCH(MAX(الأهداف!E26:E29),الأهداف!E26:E29,0))&"." -> تحقق الهدف السنوي بنسبة 96.2%، وحقق 6 أشهر من 12 هدفها؛ وأعلى المناطق تحقيقاً الجنوبية. | C15: الأهداف
A16: 11 | B16: ="أفضل موظف إيراداً "&INDEX(الموظفون!B5:B14,MATCH(1,الموظفون!J5:J14,0))&"، وأعلى نسبة تحقيق "&TEXT(MAX(الموظفون!F5:F14),"0.0%")&" لدى "&INDEX(الموظفون!B5:B14,MATCH(MAX(الموظفون!F5:F14),الموظفون!F5:F14,0))&"؛ وإجمالي العمولات "&TEXT(الموظفون!M15,"#,##0")&" ريال." -> أفضل موظف إيراداً عبدالرحمن السالم، وأعلى نسبة تحقيق 117.3% لدى شهد الكعبي؛ وإجمالي العمولات 45,621 ريال. | C16: الموظفون
A17: 12 | B17: ="تنبؤ الأشهر الثلاثة القادمة: "&TEXT('الإحصاء والتنبؤ'!B60,"#,##0")&" ريال (موسمي) مقابل "&TEXT('الإحصاء والتنبؤ'!B61,"#,##0")&" ريال (خطي)." -> تنبؤ الأشهر الثلاثة القادمة: 581,552 ريال (موسمي) مقابل 457,829 ريال (خطي). | C17: الإحصاء والتنبؤ
A18: 13 | B18: ="درجة جودة البيانات "&TEXT('جودة البيانات'!B3,"0%")&" ومطابقة الإجماليات بين الأوراق "&IF(COUNTIF('جودة البيانات'!D21:D28,"مراجعة")=0,"سليمة تماماً","تحتاج مراجعة")&"." -> درجة جودة البيانات 100% ومطابقة الإجماليات بين الأوراق سليمة تماماً. | C18: جودة البيانات
A20: ثانياً: التوصيات التنفيذية
A21: # | B21: التوصية | C21: المصدر
A22: 1 | B22: ="ضاعف المخزون والحملات قبل موسم "&INDEX('تحليل الزمن'!B5:B16,MATCH(1,'تحليل الزمن'!K5:K16,0))&"، وفعّل عروضاً محفِّزة في "&INDEX('تحليل الزمن'!B5:B16,MATCH(12,'تحليل الزمن'!K5:K16,0))&" لتقليص الفجوة الموسمية." -> ضاعف المخزون والحملات قبل موسم فبراير 2026، وفعّل عروضاً محفِّزة في يوليو 2026 لتقليص الفجوة الموسمية. | C22: تحليل الزمن
A23: 2 | B23: ="أبقِ منتجات الفئة A (عددها "&'تحليل المنتجات'!L33&") في أولوية التوريد، وراجع تسعير أو تكلفة منتجات «حجم بلا ربحية»." -> أبقِ منتجات الفئة A (عددها 16) في أولوية التوريد، وراجع تسعير أو تكلفة منتجات «حجم بلا ربحية». | C23: تحليل المنتجات
A24: 3 | B24: ="ضع سقفاً للخصم خارج المواسم؛ فالخصومات الأعلى تضغط الهامش بوضوح (ارتباط "&TEXT('الإحصاء والتنبؤ'!B30,"0.00")&")." -> ضع سقفاً للخصم خارج المواسم؛ فالخصومات الأعلى تضغط الهامش بوضوح (ارتباط -0.41). | C24: الإحصاء والتنبؤ
A25: 4 | B25: ="أطلق برنامج احتفاظ لشريحة «معرضون للفقد» ("&'تحليل العملاء'!B15&" عميلاً) وحملة إعادة تنشيط للنائمين ("&'تحليل العملاء'!B16&")." -> أطلق برنامج احتفاظ لشريحة «معرضون للفقد» (28 عميلاً) وحملة إعادة تنشيط للنائمين (27). | C25: تحليل العملاء
A26: 5 | B26: ="قلّص المرتجعات في قناة "&INDEX('الفئات والمناطق'!A24:A26,MATCH(MAX('الفئات والمناطق'!I24:I26),'الفئات والمناطق'!I24:I26,0))&" بتحسين الوصف والتغليف وسياسة الاستبدال." -> قلّص المرتجعات في قناة أونلاين بتحسين الوصف والتغليف وسياسة الاستبدال. | C26: الفئات والمناطق
A27: 6 | B27: ="ادعم أقل المناطق تحقيقاً ("&INDEX(الأهداف!A26:A29,MATCH(MIN(الأهداف!E26:E29),الأهداف!E26:E29,0))&") وراجع أهداف الموظفين دون "&TEXT(الأهداف!B5,"0%")&" من الهدف." -> ادعم أقل المناطق تحقيقاً (الشرقية) وراجع أهداف الموظفين دون 90% من الهدف. | C27: الأهداف

Sheet تحليل الزمن
A1: تحليل الاتجاه الزمني للمبيعات
A2: ↩ الفهرس | B2: الإيراد الشهري والربع سنوي، النمو، المتوسط المتحرك، مؤشر الموسمية، وأداء أيام الأسبوع
A3: أولاً: الأداء الشهري
A4: بداية الفترة | B4: الشهر | C4: الإيراد (ريال) | D4: الربح (ريال) | E4: هامش الربح | F4: الطلبات المكتملة | G4: النمو الشهري | H4: الإيراد التراكمي | I4: متوسط متحرك 3 أشهر | J4: مؤشر الموسمية | K4: ترتيب الشهر | L4: حصة الشهر
A5: =DATE(YEAR(MIN(d_Date)),MONTH(MIN(d_Date)),1) -> 45931 | B5: =CHOOSE(MONTH(A5),"يناير","فبراير","مارس","أبريل","مايو","يونيو","يوليو","أغسطس","سبتمبر","أكتوبر","نوفمبر","ديسمبر")&" "&YEAR(A5) -> أكتوبر 2025 | C5: =SUMIFS(d_Rev,d_Period,$A5) -> 186629.5 | D5: =SUMIFS(d_Profit,d_Period,$A5) -> 66799.5 | E5: =IFERROR(D5/C5,0) -> 0.35792573 | F5: =COUNTIFS(d_Period,$A5,d_Status,"مكتمل") -> 114 | G5: — | H5: =SUM($C$5:C5) -> 186629.5 | I5: =AVERAGE($C$5:C5) -> 186629.5 | J5: =IFERROR(C5/AVERAGE($C$5:$C$16),0) -> 1.0481911 | K5: =RANK(C5,$C$5:$C$16) -> 4 | L5: =IFERROR(C5/$C$17,0) -> 0.087349255
A6: =EDATE(A5,1) -> 45962 | B6: =CHOOSE(MONTH(A6),"يناير","فبراير","مارس","أبريل","مايو","يونيو","يوليو","أغسطس","سبتمبر","أكتوبر","نوفمبر","ديسمبر")&" "&YEAR(A6) -> نوفمبر 2025 | C6: =SUMIFS(d_Rev,d_Period,$A6) -> 211433 | D6: =SUMIFS(d_Profit,d_Period,$A6) -> 65588 | E6: =IFERROR(D6/C6,0) -> 0.31020702 | F6: =COUNTIFS(d_Period,$A6,d_Status,"مكتمل") -> 165 | G6: =IFERROR(C6/C5-1,0) -> 0.13290235 | H6: =SUM($C$5:C6) -> 398062.5 | I6: =AVERAGE($C$5:C6) -> 199031.25 | J6: =IFERROR(C6/AVERAGE($C$5:$C$16),0) -> 1.1874981 | K6: =RANK(C6,$C$5:$C$16) -> 2 | L6: =IFERROR(C6/$C$17,0) -> 0.098958176
A7: =EDATE(A6,1) -> 45992 | B7: =CHOOSE(MONTH(A7),"يناير","فبراير","مارس","أبريل","مايو","يونيو","يوليو","أغسطس","سبتمبر","أكتوبر","نوفمبر","ديسمبر")&" "&YEAR(A7) -> ديسمبر 2025 | C7: =SUMIFS(d_Rev,d_Period,$A7) -> 183489.5 | D7: =SUMIFS(d_Profit,d_Period,$A7) -> 66759.5 | E7: =IFERROR(D7/C7,0) -> 0.36383281 | F7: =COUNTIFS(d_Period,$A7,d_Status,"مكتمل") -> 134 | G7: =IFERROR(C7/C6-1,0) -> -0.13216243 | H7: =SUM($C$5:C7) -> 581552 | I7: =AVERAGE(C5:C7) -> 193850.67 | J7: =IFERROR(C7/AVERAGE($C$5:$C$16),0) -> 1.0305555 | K7: =RANK(C7,$C$5:$C$16) -> 5 | L7: =IFERROR(C7/$C$17,0) -> 0.085879623
A8: =EDATE(A7,1) -> 46023 | B8: =CHOOSE(MONTH(A8),"يناير","فبراير","مارس","أبريل","مايو","يونيو","يوليو","أغسطس","سبتمبر","أكتوبر","نوفمبر","ديسمبر")&" "&YEAR(A8) -> يناير 2026 | C8: =SUMIFS(d_Rev,d_Period,$A8) -> 168383.5 | D8: =SUMIFS(d_Profit,d_Period,$A8) -> 58283.5 | E8: =IFERROR(D8/C8,0) -> 0.34613546 | F8: =COUNTIFS(d_Period,$A8,d_Status,"مكتمل") -> 120 | G8: =IFERROR(C8/C7-1,0) -> -0.082326237 | H8: =SUM($C$5:C8) -> 749935.5 | I8: =AVERAGE(C6:C8) -> 187768.67 | J8: =IFERROR(C8/AVERAGE($C$5:$C$16),0) -> 0.94571372 | K8: =RANK(C8,$C$5:$C$16) -> 7 | L8: =IFERROR(C8/$C$17,0) -> 0.078809477
A9: =EDATE(A8,1) -> 46054 | B9: =CHOOSE(MONTH(A9),"يناير","فبراير","مارس","أبريل","مايو","يونيو","يوليو","أغسطس","سبتمبر","أكتوبر","نوفمبر","ديسمبر")&" "&YEAR(A9) -> فبراير 2026 | C9: =SUMIFS(d_Rev,d_Period,$A9) -> 221778.5 | D9: =SUMIFS(d_Profit,d_Period,$A9) -> 77368.5 | E9: =IFERROR(D9/C9,0) -> 0.34885483 | F9: =COUNTIFS(d_Period,$A9,d_Status,"مكتمل") -> 117 | G9: =IFERROR(C9/C8-1,0) -> 0.31710352 | H9: =SUM($C$5:C9) -> 971714 | I9: =AVERAGE(C7:C9) -> 191217.17 | J9: =IFERROR(C9/AVERAGE($C$5:$C$16),0) -> 1.2456029 | K9: =RANK(C9,$C$5:$C$16) -> 1 | L9: =IFERROR(C9/$C$17,0) -> 0.10380024
A10: =EDATE(A9,1) -> 46082 | B10: =CHOOSE(MONTH(A10),"يناير","فبراير","مارس","أبريل","مايو","يونيو","يوليو","أغسطس","سبتمبر","أكتوبر","نوفمبر","ديسمبر")&" "&YEAR(A10) -> مارس 2026 | C10: =SUMIFS(d_Rev,d_Period,$A10) -> 157027.5 | D10: =SUMIFS(d_Profit,d_Period,$A10) -> 52987.5 | E10: =IFERROR(D10/C10,0) -> 0.33744089 | F10: =COUNTIFS(d_Period,$A10,d_Status,"مكتمل") -> 119 | G10: =IFERROR(C10/C9-1,0) -> -0.29196248 | H10: =SUM($C$5:C10) -> 1128741.5 | I10: =AVERAGE(C8:C10) -> 182396.5 | J10: =IFERROR(C10/AVERAGE($C$5:$C$16),0) -> 0.88193357 | K10: =RANK(C10,$C$5:$C$16) -> 10 | L10: =IFERROR(C10/$C$17,0) -> 0.073494464
A11: =EDATE(A10,1) -> 46113 | B11: =CHOOSE(MONTH(A11),"يناير","فبراير","مارس","أبريل","مايو","يونيو","يوليو","أغسطس","سبتمبر","أكتوبر","نوفمبر","ديسمبر")&" "&YEAR(A11) -> أبريل 2026 | C11: =SUMIFS(d_Rev,d_Period,$A11) -> 166026.5 | D11: =SUMIFS(d_Profit,d_Period,$A11) -> 51891.5 | E11: =IFERROR(D11/C11,0) -> 0.3125495 | F11: =COUNTIFS(d_Period,$A11,d_Status,"مكتمل") -> 104 | G11: =IFERROR(C11/C10-1,0) -> 0.057308433 | H11: =SUM($C$5:C11) -> 1294768 | I11: =AVERAGE(C9:C11) -> 181610.83 | J11: =IFERROR(C11/AVERAGE($C$5:$C$16),0) -> 0.9324758 | K11: =RANK(C11,$C$5:$C$16) -> 8 | L11: =IFERROR(C11/$C$17,0) -> 0.077706317
A12: =EDATE(A11,1) -> 46143 | B12: =CHOOSE(MONTH(A12),"يناير","فبراير","مارس","أبريل","مايو","يونيو","يوليو","أغسطس","سبتمبر","أكتوبر","نوفمبر","ديسمبر")&" "&YEAR(A12) -> مايو 2026 | C12: =SUMIFS(d_Rev,d_Period,$A12) -> 204552.5 | D12: =SUMIFS(d_Profit,d_Period,$A12) -> 71347.5 | E12: =IFERROR(D12/C12,0) -> 0.34879799 | F12: =COUNTIFS(d_Period,$A12,d_Status,"مكتمل") -> 118 | G12: =IFERROR(C12/C11-1,0) -> 0.23204729 | H12: =SUM($C$5:C12) -> 1499320.5 | I12: =AVERAGE(C10:C12) -> 175868.83 | J12: =IFERROR(C12/AVERAGE($C$5:$C$16),0) -> 1.1488543 | K12: =RANK(C12,$C$5:$C$16) -> 3 | L12: =IFERROR(C12/$C$17,0) -> 0.095737857
A13: =EDATE(A12,1) -> 46174 | B13: =CHOOSE(MONTH(A13),"يناير","فبراير","مارس","أبريل","مايو","يونيو","يوليو","أغسطس","سبتمبر","أكتوبر","نوفمبر","ديسمبر")&" "&YEAR(A13) -> يونيو 2026 | C13: =SUMIFS(d_Rev,d_Period,$A13) -> 165984 | D13: =SUMIFS(d_Profit,d_Period,$A13) -> 51139 | E13: =IFERROR(D13/C13,0) -> 0.30809596 | F13: =COUNTIFS(d_Period,$A13,d_Status,"مكتمل") -> 116 | G13: =IFERROR(C13/C12-1,0) -> -0.18855062 | H13: =SUM($C$5:C13) -> 1665304.5 | I13: =AVERAGE(C11:C13) -> 178854.33 | J13: =IFERROR(C13/AVERAGE($C$5:$C$16),0) -> 0.9322371 | K13: =RANK(C13,$C$5:$C$16) -> 9 | L13: =IFERROR(C13/$C$17,0) -> 0.077686425
A14: =EDATE(A13,1) -> 46204 | B14: =CHOOSE(MONTH(A14),"يناير","فبراير","مارس","أبريل","مايو","يونيو","يوليو","أغسطس","سبتمبر","أكتوبر","نوفمبر","ديسمبر")&" "&YEAR(A14) -> يوليو 2026 | C14: =SUMIFS(d_Rev,d_Period,$A14) -> 137862.5 | D14: =SUMIFS(d_Profit,d_Period,$A14) -> 47002.5 | E14: =IFERROR(D14/C14,0) -> 0.34093753 | F14: =COUNTIFS(d_Period,$A14,d_Status,"مكتمل") -> 105 | G14: =IFERROR(C14/C13-1,0) -> -0.16942296 | H14: =SUM($C$5:C14) -> 1803167 | I14: =AVERAGE(C12:C14) -> 169466.33 | J14: =IFERROR(C14/AVERAGE($C$5:$C$16),0) -> 0.77429473 | K14: =RANK(C14,$C$5:$C$16) -> 12 | L14: =IFERROR(C14/$C$17,0) -> 0.064524561
A15: =EDATE(A14,1) -> 46235 | B15: =CHOOSE(MONTH(A15),"يناير","فبراير","مارس","أبريل","مايو","يونيو","يوليو","أغسطس","سبتمبر","أكتوبر","نوفمبر","ديسمبر")&" "&YEAR(A15) -> أغسطس 2026 | C15: =SUMIFS(d_Rev,d_Period,$A15) -> 153928.5 | D15: =SUMIFS(d_Profit,d_Period,$A15) -> 49338.5 | E15: =IFERROR(D15/C15,0) -> 0.32052869 | F15: =COUNTIFS(d_Period,$A15,d_Status,"مكتمل") -> 99 | G15: =IFERROR(C15/C14-1,0) -> 0.1165364 | H15: =SUM($C$5:C15) -> 1957095.5 | I15: =AVERAGE(C13:C15) -> 152591.67 | J15: =IFERROR(C15/AVERAGE($C$5:$C$16),0) -> 0.86452826 | K15: =RANK(C15,$C$5:$C$16) -> 11 | L15: =IFERROR(C15/$C$17,0) -> 0.072044022
A16: =EDATE(A15,1) -> 46266 | B16: =CHOOSE(MONTH(A16),"يناير","فبراير","مارس","أبريل","مايو","يونيو","يوليو","أغسطس","سبتمبر","أكتوبر","نوفمبر","ديسمبر")&" "&YEAR(A16) -> سبتمبر 2026 | C16: =SUMIFS(d_Rev,d_Period,$A16) -> 179494 | D16: =SUMIFS(d_Profit,d_Period,$A16) -> 57009 | E16: =IFERROR(D16/C16,0) -> 0.3176095 | F16: =COUNTIFS(d_Period,$A16,d_Status,"مكتمل") -> 123 | G16: =IFERROR(C16/C15-1,0) -> 0.16608685 | H16: =SUM($C$5:C16) -> 2136589.5 | I16: =AVERAGE(C14:C16) -> 157095 | J16: =IFERROR(C16/AVERAGE($C$5:$C$16),0) -> 1.008115 | K16: =RANK(C16,$C$5:$C$16) -> 6 | L16: =IFERROR(C16/$C$17,0) -> 0.084009586
A17: الإجمالي | B17: 12 شهراً | C17: =SUM(C5:C16) -> 2136589.5 | D17: =SUM(D5:D16) -> 715514.5 | E17: =IFERROR(D17/C17,0) -> 0.33488628 | F17: =SUM(F5:F16) -> 1434 | L17: =SUM(L5:L16) -> 1
A19: ثانياً: الأداء الربع سنوي | H19: ثالثاً: أيام الأسبوع
A20: الربع | B20: الإيراد (ريال) | C20: الربح (ريال) | D20: هامش الربح | E20: النمو عن الربع السابق | F20: الحصة | H20: # | I20: اليوم | J20: الإيراد (ريال) | K20: الطلبات | L20: متوسط قيمة الطلب
A21: 2025-Q4 | B21: =SUMIFS(d_Rev,d_Qtr,$A21) -> 581552 | C21: =SUMIFS(d_Profit,d_Qtr,$A21) -> 199147 | D21: =IFERROR(C21/B21,0) -> 0.34244057 | E21: — | F21: =IFERROR(B21/$B$25,0) -> 0.27218705 | H21: 1 | I21: الأحد | J21: =SUMPRODUCT((WEEKDAY(d_Date)=$H21)*d_Rev) -> 266123.5 | K21: =SUMPRODUCT((WEEKDAY(d_Date)=$H21)*(d_Status="مكتمل")) -> 193 | L21: =IFERROR(J21/K21,0) -> 1378.8782
A22: 2026-Q1 | B22: =SUMIFS(d_Rev,d_Qtr,$A22) -> 547189.5 | C22: =SUMIFS(d_Profit,d_Qtr,$A22) -> 188639.5 | D22: =IFERROR(C22/B22,0) -> 0.34474254 | E22: =IFERROR(B22/B21-1,0) -> -0.059087579 | F22: =IFERROR(B22/$B$25,0) -> 0.25610418 | H22: 2 | I22: الاثنين | J22: =SUMPRODUCT((WEEKDAY(d_Date)=$H22)*d_Rev) -> 225578 | K22: =SUMPRODUCT((WEEKDAY(d_Date)=$H22)*(d_Status="مكتمل")) -> 165 | L22: =IFERROR(J22/K22,0) -> 1367.1394
A23: 2026-Q2 | B23: =SUMIFS(d_Rev,d_Qtr,$A23) -> 536563 | C23: =SUMIFS(d_Profit,d_Qtr,$A23) -> 174378 | D23: =IFERROR(C23/B23,0) -> 0.32499073 | E23: =IFERROR(B23/B22-1,0) -> -0.019420146 | F23: =IFERROR(B23/$B$25,0) -> 0.2511306 | H23: 3 | I23: الثلاثاء | J23: =SUMPRODUCT((WEEKDAY(d_Date)=$H23)*d_Rev) -> 219683 | K23: =SUMPRODUCT((WEEKDAY(d_Date)=$H23)*(d_Status="مكتمل")) -> 182 | L23: =IFERROR(J23/K23,0) -> 1207.0495
A24: 2026-Q3 | B24: =SUMIFS(d_Rev,d_Qtr,$A24) -> 471285 | C24: =SUMIFS(d_Profit,d_Qtr,$A24) -> 153350 | D24: =IFERROR(C24/B24,0) -> 0.32538697 | E24: =IFERROR(B24/B23-1,0) -> -0.12165953 | F24: =IFERROR(B24/$B$25,0) -> 0.22057817 | H24: 4 | I24: الأربعاء | J24: =SUMPRODUCT((WEEKDAY(d_Date)=$H24)*d_Rev) -> 331729 | K24: =SUMPRODUCT((WEEKDAY(d_Date)=$H24)*(d_Status="مكتمل")) -> 215 | L24: =IFERROR(J24/K24,0) -> 1542.9256
A25: الإجمالي | B25: =SUM(B21:B24) -> 2136589.5 | C25: =SUM(C21:C24) -> 715514.5 | D25: =IFERROR(C25/B25,0) -> 0.33488628 | F25: =SUM(F21:F24) -> 1 | H25: 5 | I25: الخميس | J25: =SUMPRODUCT((WEEKDAY(d_Date)=$H25)*d_Rev) -> 369972.5 | K25: =SUMPRODUCT((WEEKDAY(d_Date)=$H25)*(d_Status="مكتمل")) -> 242 | L25: =IFERROR(J25/K25,0) -> 1528.812
H26: 6 | I26: الجمعة | J26: =SUMPRODUCT((WEEKDAY(d_Date)=$H26)*d_Rev) -> 394382.5 | K26: =SUMPRODUCT((WEEKDAY(d_Date)=$H26)*(d_Status="مكتمل")) -> 249 | L26: =IFERROR(J26/K26,0) -> 1583.8655
H27: 7 | I27: السبت | J27: =SUMPRODUCT((WEEKDAY(d_Date)=$H27)*d_Rev) -> 329121 | K27: =SUMPRODUCT((WEEKDAY(d_Date)=$H27)*(d_Status="مكتمل")) -> 188 | L27: =IFERROR(J27/K27,0) -> 1750.6436

Sheet الفئات والمناطق
A1: تحليل الفئات والمناطق والقنوات
A2: ↩ الفهرس | B2: جداول محورية مبنية بالصيغ (SUMIFS) مع مصفوفة المنطقة × الفئة وخريطة حرارية للهوامش
A4: أولاً: حسب الفئة
A5: الفئة | B5: الإيراد (ريال) | C5: الحصة | D5: الربح (ريال) | E5: هامش الربح | F5: الوحدات المباعة | G5: متوسط الخصم | H5: الترتيب | I5: نسبة المرتجعات
A6: إلكترونيات | B6: =SUMIFS(d_Rev,d_Cat,$A6) -> 524652.5 | C6: =IFERROR(B6/B$12,0) -> 0.24555606 | D6: =SUMIFS(d_Profit,d_Cat,$A6) -> 123282.5 | E6: =IFERROR(D6/B6,0) -> 0.23497934 | F6: =SUMIFS(d_Qty,d_Cat,$A6,d_Status,"مكتمل") -> 445 | G6: =IFERROR(AVERAGEIFS(d_Disc,d_Cat,$A6),0) -> 0.06419214 | H6: =RANK(B6,$B$6:$B$11) -> 2 | I6: =IFERROR(COUNTIFS(d_Cat,$A6,d_Status,"مرتجع")/COUNTIFS(d_Cat,$A6),0) -> 0.048034934
A7: أجهزة منزلية | B7: =SUMIFS(d_Rev,d_Cat,$A7) -> 260789 | C7: =IFERROR(B7/B$12,0) -> 0.12205854 | D7: =SUMIFS(d_Profit,d_Cat,$A7) -> 83319 | E7: =IFERROR(D7/B7,0) -> 0.31948817 | F7: =SUMIFS(d_Qty,d_Cat,$A7,d_Status,"مكتمل") -> 498 | G7: =IFERROR(AVERAGEIFS(d_Disc,d_Cat,$A7),0) -> 0.066163793 | H7: =RANK(B7,$B$6:$B$11) -> 4 | I7: =IFERROR(COUNTIFS(d_Cat,$A7,d_Status,"مرتجع")/COUNTIFS(d_Cat,$A7),0) -> 0.043103448
A8: أثاث | B8: =SUMIFS(d_Rev,d_Cat,$A8) -> 583692.5 | C8: =IFERROR(B8/B$12,0) -> 0.27318888 | D8: =SUMIFS(d_Profit,d_Cat,$A8) -> 219682.5 | E8: =IFERROR(D8/B8,0) -> 0.37636684 | F8: =SUMIFS(d_Qty,d_Cat,$A8,d_Status,"مكتمل") -> 844 | G8: =IFERROR(AVERAGEIFS(d_Disc,d_Cat,$A8),0) -> 0.073557692 | H8: =RANK(B8,$B$6:$B$11) -> 1 | I8: =IFERROR(COUNTIFS(d_Cat,$A8,d_Status,"مرتجع")/COUNTIFS(d_Cat,$A8),0) -> 0.014423077
A9: مستلزمات مكتبية | B9: =SUMIFS(d_Rev,d_Cat,$A9) -> 333618.5 | C9: =IFERROR(B9/B$12,0) -> 0.15614534 | D9: =SUMIFS(d_Profit,d_Cat,$A9) -> 107613.5 | E9: =IFERROR(D9/B9,0) -> 0.32256455 | F9: =SUMIFS(d_Qty,d_Cat,$A9,d_Status,"مكتمل") -> 1346 | G9: =IFERROR(AVERAGEIFS(d_Disc,d_Cat,$A9),0) -> 0.068272425 | H9: =RANK(B9,$B$6:$B$11) -> 3 | I9: =IFERROR(COUNTIFS(d_Cat,$A9,d_Status,"مرتجع")/COUNTIFS(d_Cat,$A9),0) -> 0.059800664
A10: رياضة | B10: =SUMIFS(d_Rev,d_Cat,$A10) -> 187066 | C10: =IFERROR(B10/B$12,0) -> 0.087553552 | D10: =SUMIFS(d_Profit,d_Cat,$A10) -> 64256 | E10: =IFERROR(D10/B10,0) -> 0.34349374 | F10: =SUMIFS(d_Qty,d_Cat,$A10,d_Status,"مكتمل") -> 386 | G10: =IFERROR(AVERAGEIFS(d_Disc,d_Cat,$A10),0) -> 0.057804878 | H10: =RANK(B10,$B$6:$B$11) -> 6 | I10: =IFERROR(COUNTIFS(d_Cat,$A10,d_Status,"مرتجع")/COUNTIFS(d_Cat,$A10),0) -> 0.034146341
A11: عناية شخصية | B11: =SUMIFS(d_Rev,d_Cat,$A11) -> 246771 | C11: =IFERROR(B11/B$12,0) -> 0.11549762 | D11: =SUMIFS(d_Profit,d_Cat,$A11) -> 117361 | E11: =IFERROR(D11/B11,0) -> 0.47558668 | F11: =SUMIFS(d_Qty,d_Cat,$A11,d_Status,"مكتمل") -> 627 | G11: =IFERROR(AVERAGEIFS(d_Disc,d_Cat,$A11),0) -> 0.062307692 | H11: =RANK(B11,$B$6:$B$11) -> 5 | I11: =IFERROR(COUNTIFS(d_Cat,$A11,d_Status,"مرتجع")/COUNTIFS(d_Cat,$A11),0) -> 0.052307692
A12: الإجمالي | B12: =SUM(B6:B11) -> 2136589.5 | C12: =SUM(C6:C11) -> 1 | D12: =SUM(D6:D11) -> 715514.5 | E12: =IFERROR(D12/B12,0) -> 0.33488628 | F12: =SUM(F6:F11) -> 4146 | G12: =AVERAGE(d_Disc) -> 0.065333333 | I12: =COUNTIF(d_Status,"مرتجع")/COUNTA(d_Status) -> 0.044
A14: ثانياً: حسب المنطقة
A15: المنطقة | B15: الإيراد (ريال) | C15: الحصة | D15: الربح (ريال) | E15: هامش الربح | F15: الوحدات المباعة | G15: متوسط الخصم | H15: الترتيب | I15: نسبة المرتجعات
A16: الوسطى | B16: =SUMIFS(d_Rev,d_Region,$A16) -> 692926.5 | C16: =IFERROR(B16/B$20,0) -> 0.32431429 | D16: =SUMIFS(d_Profit,d_Region,$A16) -> 228961.5 | E16: =IFERROR(D16/B16,0) -> 0.33042682 | F16: =SUMIFS(d_Qty,d_Region,$A16,d_Status,"مكتمل") -> 1389 | G16: =IFERROR(AVERAGEIFS(d_Disc,d_Region,$A16),0) -> 0.06208577 | H16: =RANK(B16,$B$16:$B$19) -> 1 | I16: =IFERROR(COUNTIFS(d_Region,$A16,d_Status,"مرتجع")/COUNTIFS(d_Region,$A16),0) -> 0.038986355
A17: الغربية | B17: =SUMIFS(d_Rev,d_Region,$A17) -> 565303 | C17: =IFERROR(B17/B$20,0) -> 0.26458194 | D17: =SUMIFS(d_Profit,d_Region,$A17) -> 186963 | E17: =IFERROR(D17/B17,0) -> 0.3307306 | F17: =SUMIFS(d_Qty,d_Region,$A17,d_Status,"مكتمل") -> 1044 | G17: =IFERROR(AVERAGEIFS(d_Disc,d_Region,$A17),0) -> 0.065135135 | H17: =RANK(B17,$B$16:$B$19) -> 2 | I17: =IFERROR(COUNTIFS(d_Region,$A17,d_Status,"مرتجع")/COUNTIFS(d_Region,$A17),0) -> 0.045945946
A18: الشرقية | B18: =SUMIFS(d_Rev,d_Region,$A18) -> 499447 | C18: =IFERROR(B18/B$20,0) -> 0.23375899 | D18: =SUMIFS(d_Profit,d_Region,$A18) -> 168442 | E18: =IFERROR(D18/B18,0) -> 0.33725701 | F18: =SUMIFS(d_Qty,d_Region,$A18,d_Status,"مكتمل") -> 907 | G18: =IFERROR(AVERAGEIFS(d_Disc,d_Region,$A18),0) -> 0.06937046 | H18: =RANK(B18,$B$16:$B$19) -> 3 | I18: =IFERROR(COUNTIFS(d_Region,$A18,d_Status,"مرتجع")/COUNTIFS(d_Region,$A18),0) -> 0.055690073
A19: الجنوبية | B19: =SUMIFS(d_Rev,d_Region,$A19) -> 378913 | C19: =IFERROR(B19/B$20,0) -> 0.17734478 | D19: =SUMIFS(d_Profit,d_Region,$A19) -> 131148 | E19: =IFERROR(D19/B19,0) -> 0.34611639 | F19: =SUMIFS(d_Qty,d_Region,$A19,d_Status,"مكتمل") -> 806 | G19: =IFERROR(AVERAGEIFS(d_Disc,d_Region,$A19),0) -> 0.065686275 | H19: =RANK(B19,$B$16:$B$19) -> 4 | I19: =IFERROR(COUNTIFS(d_Region,$A19,d_Status,"مرتجع")/COUNTIFS(d_Region,$A19),0) -> 0.029411765
A20: الإجمالي | B20: =SUM(B16:B19) -> 2136589.5 | C20: =SUM(C16:C19) -> 1 | D20: =SUM(D16:D19) -> 715514.5 | E20: =IFERROR(D20/B20,0) -> 0.33488628 | F20: =SUM(F16:F19) -> 4146 | G20: =AVERAGE(d_Disc) -> 0.065333333 | I20: =COUNTIF(d_Status,"مرتجع")/COUNTA(d_Status) -> 0.044
A22: ثالثاً: حسب القناة
A23: القناة | B23: الإيراد (ريال) | C23: الحصة | D23: الربح (ريال) | E23: هامش الربح | F23: الوحدات المباعة | G23: متوسط الخصم | H23: الترتيب | I23: نسبة المرتجعات
A24: متجر | B24: =SUMIFS(d_Rev,d_Channel,$A24) -> 844286.5 | C24: =IFERROR(B24/B$27,0) -> 0.39515616 | D24: =SUMIFS(d_Profit,d_Channel,$A24) -> 285611.5 | E24: =IFERROR(D24/B24,0) -> 0.33828742 | F24: =SUMIFS(d_Qty,d_Channel,$A24,d_Status,"مكتمل") -> 1533 | G24: =IFERROR(AVERAGEIFS(d_Disc,d_Channel,$A24),0) -> 0.058916324 | H24: =RANK(B24,$B$24:$B$26) -> 1 | I24: =IFERROR(COUNTIFS(d_Channel,$A24,d_Status,"مرتجع")/COUNTIFS(d_Channel,$A24),0) -> 0.0260631
A25: أونلاين | B25: =SUMIFS(d_Rev,d_Channel,$A25) -> 830453.5 | C25: =IFERROR(B25/B$27,0) -> 0.38868182 | D25: =SUMIFS(d_Profit,d_Channel,$A25) -> 280143.5 | E25: =IFERROR(D25/B25,0) -> 0.33733797 | F25: =SUMIFS(d_Qty,d_Channel,$A25,d_Status,"مكتمل") -> 1543 | G25: =IFERROR(AVERAGEIFS(d_Disc,d_Channel,$A25),0) -> 0.065361446 | H25: =RANK(B25,$B$24:$B$26) -> 2 | I25: =IFERROR(COUNTIFS(d_Channel,$A25,d_Status,"مرتجع")/COUNTIFS(d_Channel,$A25),0) -> 0.064759036
A26: جملة | B26: =SUMIFS(d_Rev,d_Channel,$A26) -> 461849.5 | C26: =IFERROR(B26/B$27,0) -> 0.21616202 | D26: =SUMIFS(d_Profit,d_Channel,$A26) -> 149759.5 | E26: =IFERROR(D26/B26,0) -> 0.32426039 | F26: =SUMIFS(d_Qty,d_Channel,$A26,d_Status,"مكتمل") -> 1070 | G26: =IFERROR(AVERAGEIFS(d_Disc,d_Channel,$A26),0) -> 0.1088785 | H26: =RANK(B26,$B$24:$B$26) -> 3 | I26: =IFERROR(COUNTIFS(d_Channel,$A26,d_Status,"مرتجع")/COUNTIFS(d_Channel,$A26),0) -> 0.037383178
A27: الإجمالي | B27: =SUM(B24:B26) -> 2136589.5 | C27: =SUM(C24:C26) -> 1 | D27: =SUM(D24:D26) -> 715514.5 | E27: =IFERROR(D27/B27,0) -> 0.33488628 | F27: =SUM(F24:F26) -> 4146 | G27: =AVERAGE(d_Disc) -> 0.065333333 | I27: =COUNTIF(d_Status,"مرتجع")/COUNTA(d_Status) -> 0.044
A29: رابعاً: مصفوفة الإيراد — المنطقة × الفئة
A30: المنطقة | B30: إلكترونيات | C30: أجهزة منزلية | D30: أثاث | E30: مستلزمات مكتبية | F30: رياضة | G30: عناية شخصية | H30: الإجمالي
A31: الوسطى | B31: =SUMIFS(d_Rev,d_Region,$A31,d_Cat,B$30) -> 183490 | C31: =SUMIFS(d_Rev,d_Region,$A31,d_Cat,C$30) -> 104532 | D31: =SUMIFS(d_Rev,d_Region,$A31,d_Cat,D$30) -> 134040 | E31: =SUMIFS(d_Rev,d_Region,$A31,d_Cat,E$30) -> 128393.5 | F31: =SUMIFS(d_Rev,d_Region,$A31,d_Cat,F$30) -> 59532 | G31: =SUMIFS(d_Rev,d_Region,$A31,d_Cat,G$30) -> 82939 | H31: =SUM(B31:G31) -> 692926.5
A32: الغربية | B32: =SUMIFS(d_Rev,d_Region,$A32,d_Cat,B$30) -> 148547.5 | C32: =SUMIFS(d_Rev,d_Region,$A32,d_Cat,C$30) -> 53750.5 | D32: =SUMIFS(d_Rev,d_Region,$A32,d_Cat,D$30) -> 160317.5 | E32: =SUMIFS(d_Rev,d_Region,$A32,d_Cat,E$30) -> 81141.5 | F32: =SUMIFS(d_Rev,d_Region,$A32,d_Cat,F$30) -> 58724 | G32: =SUMIFS(d_Rev,d_Region,$A32,d_Cat,G$30) -> 62822 | H32: =SUM(B32:G32) -> 565303
A33: الشرقية | B33: =SUMIFS(d_Rev,d_Region,$A33,d_Cat,B$30) -> 123372.5 | C33: =SUMIFS(d_Rev,d_Region,$A33,d_Cat,C$30) -> 58860 | D33: =SUMIFS(d_Rev,d_Region,$A33,d_Cat,D$30) -> 152025 | E33: =SUMIFS(d_Rev,d_Region,$A33,d_Cat,E$30) -> 47357.5 | F33: =SUMIFS(d_Rev,d_Region,$A33,d_Cat,F$30) -> 44036 | G33: =SUMIFS(d_Rev,d_Region,$A33,d_Cat,G$30) -> 73796 | H33: =SUM(B33:G33) -> 499447
A34: الجنوبية | B34: =SUMIFS(d_Rev,d_Region,$A34,d_Cat,B$30) -> 69242.5 | C34: =SUMIFS(d_Rev,d_Region,$A34,d_Cat,C$30) -> 43646.5 | D34: =SUMIFS(d_Rev,d_Region,$A34,d_Cat,D$30) -> 137310 | E34: =SUMIFS(d_Rev,d_Region,$A34,d_Cat,E$30) -> 76726 | F34: =SUMIFS(d_Rev,d_Region,$A34,d_Cat,F$30) -> 24774 | G34: =SUMIFS(d_Rev,d_Region,$A34,d_Cat,G$30) -> 27214 | H34: =SUM(B34:G34) -> 378913
A35: الإجمالي | B35: =SUM(B31:B34) -> 524652.5 | C35: =SUM(C31:C34) -> 260789 | D35: =SUM(D31:D34) -> 583692.5 | E35: =SUM(E31:E34) -> 333618.5 | F35: =SUM(F31:F34) -> 187066 | G35: =SUM(G31:G34) -> 246771 | H35: =SUM(H31:H34) -> 2136589.5
A37: خامساً: خريطة حرارية لهامش الربح — المنطقة × الفئة
A38: المنطقة | B38: إلكترونيات | C38: أجهزة منزلية | D38: أثاث | E38: مستلزمات مكتبية | F38: رياضة | G38: عناية شخصية | H38: الإجمالي
A39: الوسطى | B39: =IFERROR(SUMIFS(d_Profit,d_Region,$A39,d_Cat,B$38)/SUMIFS(d_Rev,d_Region,$A39,d_Cat,B$38),0) -> 0.2438825 | C39: =IFERROR(SUMIFS(d_Profit,d_Region,$A39,d_Cat,C$38)/SUMIFS(d_Rev,d_Region,$A39,d_Cat,C$38),0) -> 0.31317683 | D39: =IFERROR(SUMIFS(d_Profit,d_Region,$A39,d_Cat,D$38)/SUMIFS(d_Rev,d_Region,$A39,d_Cat,D$38),0) -> 0.37354521 | E39: =IFERROR(SUMIFS(d_Profit,d_Region,$A39,d_Cat,E$38)/SUMIFS(d_Rev,d_Region,$A39,d_Cat,E$38),0) -> 0.3164763 | F39: =IFERROR(SUMIFS(d_Profit,d_Region,$A39,d_Cat,F$38)/SUMIFS(d_Rev,d_Region,$A39,d_Cat,F$38),0) -> 0.35127326 | G39: =IFERROR(SUMIFS(d_Profit,d_Region,$A39,d_Cat,G$38)/SUMIFS(d_Rev,d_Region,$A39,d_Cat,G$38),0) -> 0.48058211 | H39: =IFERROR(SUMIFS(d_Profit,d_Region,$A39)/SUMIFS(d_Rev,d_Region,$A39),0) -> 0.33042682
A40: الغربية | B40: =IFERROR(SUMIFS(d_Profit,d_Region,$A40,d_Cat,B$38)/SUMIFS(d_Rev,d_Region,$A40,d_Cat,B$38),0) -> 0.23196284 | C40: =IFERROR(SUMIFS(d_Profit,d_Region,$A40,d_Cat,C$38)/SUMIFS(d_Rev,d_Region,$A40,d_Cat,C$38),0) -> 0.33702942 | D40: =IFERROR(SUMIFS(d_Profit,d_Region,$A40,d_Cat,D$38)/SUMIFS(d_Rev,d_Region,$A40,d_Cat,D$38),0) -> 0.37916946 | E40: =IFERROR(SUMIFS(d_Profit,d_Region,$A40,d_Cat,E$38)/SUMIFS(d_Rev,d_Region,$A40,d_Cat,E$38),0) -> 0.31003247 | F40: =IFERROR(SUMIFS(d_Profit,d_Region,$A40,d_Cat,F$38)/SUMIFS(d_Rev,d_Region,$A40,d_Cat,F$38),0) -> 0.33110824 | G40: =IFERROR(SUMIFS(d_Profit,d_Region,$A40,d_Cat,G$38)/SUMIFS(d_Rev,d_Region,$A40,d_Cat,G$38),0) -> 0.46165356 | H40: =IFERROR(SUMIFS(d_Profit,d_Region,$A40)/SUMIFS(d_Rev,d_Region,$A40),0) -> 0.3307306
A41: الشرقية | B41: =IFERROR(SUMIFS(d_Profit,d_Region,$A41,d_Cat,B$38)/SUMIFS(d_Rev,d_Region,$A41,d_Cat,B$38),0) -> 0.23783663 | C41: =IFERROR(SUMIFS(d_Profit,d_Region,$A41,d_Cat,C$38)/SUMIFS(d_Rev,d_Region,$A41,d_Cat,C$38),0) -> 0.32050629 | D41: =IFERROR(SUMIFS(d_Profit,d_Region,$A41,d_Cat,D$38)/SUMIFS(d_Rev,d_Region,$A41,d_Cat,D$38),0) -> 0.36714356 | E41: =IFERROR(SUMIFS(d_Profit,d_Region,$A41,d_Cat,E$38)/SUMIFS(d_Rev,d_Region,$A41,d_Cat,E$38),0) -> 0.3025392 | F41: =IFERROR(SUMIFS(d_Profit,d_Region,$A41,d_Cat,F$38)/SUMIFS(d_Rev,d_Region,$A41,d_Cat,F$38),0) -> 0.33009356 | G41: =IFERROR(SUMIFS(d_Profit,d_Region,$A41,d_Cat,G$38)/SUMIFS(d_Rev,d_Region,$A41,d_Cat,G$38),0) -> 0.48181473 | H41: =IFERROR(SUMIFS(d_Profit,d_Region,$A41)/SUMIFS(d_Rev,d_Region,$A41),0) -> 0.33725701
A42: الجنوبية | B42: =IFERROR(SUMIFS(d_Profit,d_Region,$A42,d_Cat,B$38)/SUMIFS(d_Rev,d_Region,$A42,d_Cat,B$38),0) -> 0.21276673 | C42: =IFERROR(SUMIFS(d_Profit,d_Region,$A42,d_Cat,C$38)/SUMIFS(d_Rev,d_Region,$A42,d_Cat,C$38),0) -> 0.31162865 | D42: =IFERROR(SUMIFS(d_Profit,d_Region,$A42,d_Cat,D$38)/SUMIFS(d_Rev,d_Region,$A42,d_Cat,D$38),0) -> 0.38606074 | E42: =IFERROR(SUMIFS(d_Profit,d_Region,$A42,d_Cat,E$38)/SUMIFS(d_Rev,d_Region,$A42,d_Cat,E$38),0) -> 0.35836613 | F42: =IFERROR(SUMIFS(d_Profit,d_Region,$A42,d_Cat,F$38)/SUMIFS(d_Rev,d_Region,$A42,d_Cat,F$38),0) -> 0.37797691 | G42: =IFERROR(SUMIFS(d_Profit,d_Region,$A42,d_Cat,G$38)/SUMIFS(d_Rev,d_Region,$A42,d_Cat,G$38),0) -> 0.47563754 | H42: =IFERROR(SUMIFS(d_Profit,d_Region,$A42)/SUMIFS(d_Rev,d_Region,$A42),0) -> 0.34611639

Sheet تحليل المنتجات
A1: تحليل المنتجات وباريتو (ABC)
A2: ↩ الفهرس | B2: ترتيب المنتجات، تصنيف الأداء (الإيراد × الهامش)، وقاعدة 80/20
A4: أداء المنتجات | K4: الترتيب التنازلي وتحليل باريتو
A5: رقم المنتج | B5: المنتج | C5: الفئة | D5: الوحدات | E5: الإيراد (ريال) | F5: الربح (ريال) | G5: هامش الربح | H5: الترتيب | I5: تصنيف الأداء | K5: الترتيب | L5: المنتج | M5: الإيراد (ريال) | N5: الحصة | O5: التراكمي | P5: تصنيف ABC | Q5: الهامش
A6: P001 | B6: =INDEX(p_Name,MATCH($A6,p_ID,0)) -> هاتف ذكي | C6: =INDEX(p_Cat,MATCH($A6,p_ID,0)) -> إلكترونيات | D6: =SUMIFS(d_Qty,d_PID,$A6,d_Status,"مكتمل") -> 83 | E6: =SUMIFS(d_Rev,d_PID,$A6) -> 186000 | F6: =SUMIFS(d_Profit,d_PID,$A6) -> 40750 | G6: =IFERROR(F6/E6,0) -> 0.21908602 | H6: =RANK(E6,$E$6:$E$29)+COUNTIF($E$6:E6,E6)-1 -> 2 | I6: =IF(E6>=AVERAGE($E$6:$E$29),IF(G6>=$G$30,"نجم","حجم بلا ربحية"),IF(G6>=$G$30,"فرصة نمو","يحتاج مراجعة")) -> حجم بلا ربحية | K6: 1 | L6: =INDEX($B$6:$B$29,MATCH($K6,$H$6:$H$29,0)) -> مكتب عمل | M6: =INDEX($E$6:$E$29,MATCH($K6,$H$6:$H$29,0)) -> 243780 | N6: =IFERROR(M6/$E$30,0) -> 0.11409772 | O6: =SUM($N$6:N6) -> 0.11409772 | P6: =IF(O6-N6<0.8,"A",IF(O6-N6<0.95,"B","C")) -> A | Q6: =INDEX($G$6:$G$29,MATCH($K6,$H$6:$H$29,0)) -> 0.3768972
A7: P002 | B7: =INDEX(p_Name,MATCH($A7,p_ID,0)) -> حاسوب محمول | C7: =INDEX(p_Cat,MATCH($A7,p_ID,0)) -> إلكترونيات | D7: =SUMIFS(d_Qty,d_PID,$A7,d_Status,"مكتمل") -> 33 | E7: =SUMIFS(d_Rev,d_PID,$A7) -> 117610 | F7: =SUMIFS(d_Profit,d_PID,$A7) -> 21910 | G7: =IFERROR(F7/E7,0) -> 0.18629368 | H7: =RANK(E7,$E$6:$E$29)+COUNTIF($E$6:E7,E7)-1 -> 5 | I7: =IF(E7>=AVERAGE($E$6:$E$29),IF(G7>=$G$30,"نجم","حجم بلا ربحية"),IF(G7>=$G$30,"فرصة نمو","يحتاج مراجعة")) -> حجم بلا ربحية | K7: 2 | L7: =INDEX($B$6:$B$29,MATCH($K7,$H$6:$H$29,0)) -> هاتف ذكي | M7: =INDEX($E$6:$E$29,MATCH($K7,$H$6:$H$29,0)) -> 186000 | N7: =IFERROR(M7/$E$30,0) -> 0.087054626 | O7: =SUM($N$6:N7) -> 0.20115235 | P7: =IF(O7-N7<0.8,"A",IF(O7-N7<0.95,"B","C")) -> A | Q7: =INDEX($G$6:$G$29,MATCH($K7,$H$6:$H$29,0)) -> 0.21908602
A8: P003 | B8: =INDEX(p_Name,MATCH($A8,p_ID,0)) -> سماعات لاسلكية | C8: =INDEX(p_Cat,MATCH($A8,p_ID,0)) -> إلكترونيات | D8: =SUMIFS(d_Qty,d_PID,$A8,d_Status,"مكتمل") -> 185 | E8: =SUMIFS(d_Rev,d_PID,$A8) -> 77107.5 | F8: =SUMIFS(d_Profit,d_PID,$A8) -> 29007.5 | G8: =IFERROR(F8/E8,0) -> 0.37619557 | H8: =RANK(E8,$E$6:$E$29)+COUNTIF($E$6:E8,E8)-1 -> 10 | I8: =IF(E8>=AVERAGE($E$6:$E$29),IF(G8>=$G$30,"نجم","حجم بلا ربحية"),IF(G8>=$G$30,"فرصة نمو","يحتاج مراجعة")) -> فرصة نمو | K8: 3 | L8: =INDEX($B$6:$B$29,MATCH($K8,$H$6:$H$29,0)) -> طابعة ليزر | M8: =INDEX($E$6:$E$29,MATCH($K8,$H$6:$H$29,0)) -> 161915 | N8: =IFERROR(M8/$E$30,0) -> 0.075781988 | O8: =SUM($N$6:N8) -> 0.27693434 | P8: =IF(O8-N8<0.8,"A",IF(O8-N8<0.95,"B","C")) -> A | Q8: =INDEX($G$6:$G$29,MATCH($K8,$H$6:$H$29,0)) -> 0.22551956
A9: P004 | B9: =INDEX(p_Name,MATCH($A9,p_ID,0)) -> شاشة 27 بوصة | C9: =INDEX(p_Cat,MATCH($A9,p_ID,0)) -> إلكترونيات | D9: =SUMIFS(d_Qty,d_PID,$A9,d_Status,"مكتمل") -> 144 | E9: =SUMIFS(d_Rev,d_PID,$A9) -> 143935 | F9: =SUMIFS(d_Profit,d_PID,$A9) -> 31615 | G9: =IFERROR(F9/E9,0) -> 0.21964776 | H9: =RANK(E9,$E$6:$E$29)+COUNTIF($E$6:E9,E9)-1 -> 4 | I9: =IF(E9>=AVERAGE($E$6:$E$29),IF(G9>=$G$30,"نجم","حجم بلا ربحية"),IF(G9>=$G$30,"فرصة نمو","يحتاج مراجعة")) -> حجم بلا ربحية | K9: 4 | L9: =INDEX($B$6:$B$29,MATCH($K9,$H$6:$H$29,0)) -> شاشة 27 بوصة | M9: =INDEX($E$6:$E$29,MATCH($K9,$H$6:$H$29,0)) -> 143935 | N9: =IFERROR(M9/$E$30,0) -> 0.067366708 | O9: =SUM($N$6:N9) -> 0.34430105 | P9: =IF(O9-N9<0.8,"A",IF(O9-N9<0.95,"B","C")) -> A | Q9: =INDEX($G$6:$G$29,MATCH($K9,$H$6:$H$29,0)) -> 0.21964776
A10: P005 | B10: =INDEX(p_Name,MATCH($A10,p_ID,0)) -> مكنسة كهربائية | C10: =INDEX(p_Cat,MATCH($A10,p_ID,0)) -> أجهزة منزلية | D10: =SUMIFS(d_Qty,d_PID,$A10,d_Status,"مكتمل") -> 131 | E10: =SUMIFS(d_Rev,d_PID,$A10) -> 79625 | F10: =SUMIFS(d_Profit,d_PID,$A10) -> 24605 | G10: =IFERROR(F10/E10,0) -> 0.30901099 | H10: =RANK(E10,$E$6:$E$29)+COUNTIF($E$6:E10,E10)-1 -> 9 | I10: =IF(E10>=AVERAGE($E$6:$E$29),IF(G10>=$G$30,"نجم","حجم بلا ربحية"),IF(G10>=$G$30,"فرصة نمو","يحتاج مراجعة")) -> يحتاج مراجعة | K10: 5 | L10: =INDEX($B$6:$B$29,MATCH($K10,$H$6:$H$29,0)) -> حاسوب محمول | M10: =INDEX($E$6:$E$29,MATCH($K10,$H$6:$H$29,0)) -> 117610 | N10: =IFERROR(M10/$E$30,0) -> 0.05504567 | O10: =SUM($N$6:N10) -> 0.39934672 | P10: =IF(O10-N10<0.8,"A",IF(O10-N10<0.95,"B","C")) -> A | Q10: =INDEX($G$6:$G$29,MATCH($K10,$H$6:$H$29,0)) -> 0.18629368
A11: P006 | B11: =INDEX(p_Name,MATCH($A11,p_ID,0)) -> خلاط | C11: =INDEX(p_Cat,MATCH($A11,p_ID,0)) -> أجهزة منزلية | D11: =SUMIFS(d_Qty,d_PID,$A11,d_Status,"مكتمل") -> 212 | E11: =SUMIFS(d_Rev,d_PID,$A11) -> 59550 | F11: =SUMIFS(d_Profit,d_PID,$A11) -> 22450 | G11: =IFERROR(F11/E11,0) -> 0.37699412 | H11: =RANK(E11,$E$6:$E$29)+COUNTIF($E$6:E11,E11)-1 -> 16 | I11: =IF(E11>=AVERAGE($E$6:$E$29),IF(G11>=$G$30,"نجم","حجم بلا ربحية"),IF(G11>=$G$30,"فرصة نمو","يحتاج مراجعة")) -> فرصة نمو | K11: 6 | L11: =INDEX($B$6:$B$29,MATCH($K11,$H$6:$H$29,0)) -> كرسي مريح | M11: =INDEX($E$6:$E$29,MATCH($K11,$H$6:$H$29,0)) -> 116407.5 | N11: =IFERROR(M11/$E$30,0) -> 0.054482857 | O11: =SUM($N$6:N11) -> 0.45382957 | P11: =IF(O11-N11<0.8,"A",IF(O11-N11<0.95,"B","C")) -> A | Q11: =INDEX($G$6:$G$29,MATCH($K11,$H$6:$H$29,0)) -> 0.36911281
A12: P007 | B12: =INDEX(p_Name,MATCH($A12,p_ID,0)) -> مكيف نقال | C12: =INDEX(p_Cat,MATCH($A12,p_ID,0)) -> أجهزة منزلية | D12: =SUMIFS(d_Qty,d_PID,$A12,d_Status,"مكتمل") -> 37 | E12: =SUMIFS(d_Rev,d_PID,$A12) -> 65740 | F12: =SUMIFS(d_Profit,d_PID,$A12) -> 15790 | G12: =IFERROR(F12/E12,0) -> 0.24018862 | H12: =RANK(E12,$E$6:$E$29)+COUNTIF($E$6:E12,E12)-1 -> 14 | I12: =IF(E12>=AVERAGE($E$6:$E$29),IF(G12>=$G$30,"نجم","حجم بلا ربحية"),IF(G12>=$G$30,"فرصة نمو","يحتاج مراجعة")) -> يحتاج مراجعة | K12: 7 | L12: =INDEX($B$6:$B$29,MATCH($K12,$H$6:$H$29,0)) -> خزانة ملفات | M12: =INDEX($E$6:$E$29,MATCH($K12,$H$6:$H$29,0)) -> 115885 | N12: =IFERROR(M12/$E$30,0) -> 0.054238308 | O12: =SUM($N$6:N12) -> 0.50806788 | P12: =IF(O12-N12<0.8,"A",IF(O12-N12<0.95,"B","C")) -> A | Q12: =INDEX($G$6:$G$29,MATCH($K12,$H$6:$H$29,0)) -> 0.35962376
A13: P008 | B13: =INDEX(p_Name,MATCH($A13,p_ID,0)) -> قلاية هوائية | C13: =INDEX(p_Cat,MATCH($A13,p_ID,0)) -> أجهزة منزلية | D13: =SUMIFS(d_Qty,d_PID,$A13,d_Status,"مكتمل") -> 118 | E13: =SUMIFS(d_Rev,d_PID,$A13) -> 55874 | F13: =SUMIFS(d_Profit,d_PID,$A13) -> 20474 | G13: =IFERROR(F13/E13,0) -> 0.36643161 | H13: =RANK(E13,$E$6:$E$29)+COUNTIF($E$6:E13,E13)-1 -> 19 | I13: =IF(E13>=AVERAGE($E$6:$E$29),IF(G13>=$G$30,"نجم","حجم بلا ربحية"),IF(G13>=$G$30,"فرصة نمو","يحتاج مراجعة")) -> فرصة نمو | K13: 8 | L13: =INDEX($B$6:$B$29,MATCH($K13,$H$6:$H$29,0)) -> رف كتب | M13: =INDEX($E$6:$E$29,MATCH($K13,$H$6:$H$29,0)) -> 107620 | N13: =IFERROR(M13/$E$30,0) -> 0.050369994 | O13: =SUM($N$6:N13) -> 0.55843787 | P13: =IF(O13-N13<0.8,"A",IF(O13-N13<0.95,"B","C")) -> A | Q13: =INDEX($G$6:$G$29,MATCH($K13,$H$6:$H$29,0)) -> 0.4010407
A14: P009 | B14: =INDEX(p_Name,MATCH($A14,p_ID,0)) -> مكتب عمل | C14: =INDEX(p_Cat,MATCH($A14,p_ID,0)) -> أثاث | D14: =SUMIFS(d_Qty,d_PID,$A14,d_Status,"مكتمل") -> 217 | E14: =SUMIFS(d_Rev,d_PID,$A14) -> 243780 | F14: =SUMIFS(d_Profit,d_PID,$A14) -> 91880 | G14: =IFERROR(F14/E14,0) -> 0.3768972 | H14: =RANK(E14,$E$6:$E$29)+COUNTIF($E$6:E14,E14)-1 -> 1 | I14: =IF(E14>=AVERAGE($E$6:$E$29),IF(G14>=$G$30,"نجم","حجم بلا ربحية"),IF(G14>=$G$30,"فرصة نمو","يحتاج مراجعة")) -> نجم | K14: 9 | L14: =INDEX($B$6:$B$29,MATCH($K14,$H$6:$H$29,0)) -> مكنسة كهربائية | M14: =INDEX($E$6:$E$29,MATCH($K14,$H$6:$H$29,0)) -> 79625 | N14: =IFERROR(M14/$E$30,0) -> 0.037267337 | O14: =SUM($N$6:N14) -> 0.59570521 | P14: =IF(O14-N14<0.8,"A",IF(O14-N14<0.95,"B","C")) -> A | Q14: =INDEX($G$6:$G$29,MATCH($K14,$H$6:$H$29,0)) -> 0.30901099
A15: P010 | B15: =INDEX(p_Name,MATCH($A15,p_ID,0)) -> كرسي مريح | C15: =INDEX(p_Cat,MATCH($A15,p_ID,0)) -> أثاث | D15: =SUMIFS(d_Qty,d_PID,$A15,d_Status,"مكتمل") -> 153 | E15: =SUMIFS(d_Rev,d_PID,$A15) -> 116407.5 | F15: =SUMIFS(d_Profit,d_PID,$A15) -> 42967.5 | G15: =IFERROR(F15/E15,0) -> 0.36911281 | H15: =RANK(E15,$E$6:$E$29)+COUNTIF($E$6:E15,E15)-1 -> 6 | I15: =IF(E15>=AVERAGE($E$6:$E$29),IF(G15>=$G$30,"نجم","حجم بلا ربحية"),IF(G15>=$G$30,"فرصة نمو","يحتاج مراجعة")) -> نجم | K15: 10 | L15: =INDEX($B$6:$B$29,MATCH($K15,$H$6:$H$29,0)) -> سماعات لاسلكية | M15: =INDEX($E$6:$E$29,MATCH($K15,$H$6:$H$29,0)) -> 77107.5 | N15: =IFERROR(M15/$E$30,0) -> 0.036089057 | O15: =SUM($N$6:N15) -> 0.63179427 | P15: =IF(O15-N15<0.8,"A",IF(O15-N15<0.95,"B","C")) -> A | Q15: =INDEX($G$6:$G$29,MATCH($K15,$H$6:$H$29,0)) -> 0.37619557
A16: P011 | B16: =INDEX(p_Name,MATCH($A16,p_ID,0)) -> خزانة ملفات | C16: =INDEX(p_Cat,MATCH($A16,p_ID,0)) -> أثاث | D16: =SUMIFS(d_Qty,d_PID,$A16,d_Status,"مكتمل") -> 181 | E16: =SUMIFS(d_Rev,d_PID,$A16) -> 115885 | F16: =SUMIFS(d_Profit,d_PID,$A16) -> 41675 | G16: =IFERROR(F16/E16,0) -> 0.35962376 | H16: =RANK(E16,$E$6:$E$29)+COUNTIF($E$6:E16,E16)-1 -> 7 | I16: =IF(E16>=AVERAGE($E$6:$E$29),IF(G16>=$G$30,"نجم","حجم بلا ربحية"),IF(G16>=$G$30,"فرصة نمو","يحتاج مراجعة")) -> نجم | K16: 11 | L16: =INDEX($B$6:$B$29,MATCH($K16,$H$6:$H$29,0)) -> حقيبة لابتوب | M16: =INDEX($E$6:$E$29,MATCH($K16,$H$6:$H$29,0)) -> 76765 | N16: =IFERROR(M16/$E$30,0) -> 0.035928755 | O16: =SUM($N$6:N16) -> 0.66772302 | P16: =IF(O16-N16<0.8,"A",IF(O16-N16<0.95,"B","C")) -> A | Q16: =INDEX($G$6:$G$29,MATCH($K16,$H$6:$H$29,0)) -> 0.50133524
A17: P012 | B17: =INDEX(p_Name,MATCH($A17,p_ID,0)) -> رف كتب | C17: =INDEX(p_Cat,MATCH($A17,p_ID,0)) -> أثاث | D17: =SUMIFS(d_Qty,d_PID,$A17,d_Status,"مكتمل") -> 293 | E17: =SUMIFS(d_Rev,d_PID,$A17) -> 107620 | F17: =SUMIFS(d_Profit,d_PID,$A17) -> 43160 | G17: =IFERROR(F17/E17,0) -> 0.4010407 | H17: =RANK(E17,$E$6:$E$29)+COUNTIF($E$6:E17,E17)-1 -> 8 | I17: =IF(E17>=AVERAGE($E$6:$E$29),IF(G17>=$G$30,"نجم","حجم بلا ربحية"),IF(G17>=$G$30,"فرصة نمو","يحتاج مراجعة")) -> نجم | K17: 12 | L17: =INDEX($B$6:$B$29,MATCH($K17,$H$6:$H$29,0)) -> جهاز تدليك | M17: =INDEX($E$6:$E$29,MATCH($K17,$H$6:$H$29,0)) -> 75000 | N17: =IFERROR(M17/$E$30,0) -> 0.035102672 | O17: =SUM($N$6:N17) -> 0.70282569 | P17: =IF(O17-N17<0.8,"A",IF(O17-N17<0.95,"B","C")) -> A | Q17: =INDEX($G$6:$G$29,MATCH($K17,$H$6:$H$29,0)) -> 0.4016
... A29: P024 | B29: =INDEX(p_Name,MATCH($A29,p_ID,0)) -> جهاز تدليك | C29: =INDEX(p_Cat,MATCH($A29,p_ID,0)) -> عناية شخصية | D29: =SUMIFS(d_Qty,d_PID,$A29,d_Status,"مكتمل") -> 136 | E29: =SUMIFS(d_Rev,d_PID,$A29) -> 75000 | F29: =SUMIFS(d_Profit,d_PID,$A29) -> 30120 | G29: =IFERROR(F29/E29,0) -> 0.4016 | H29: =RANK(E29,$E$6:$E$29)+COUNTIF($E$6:E29,E29)-1 -> 12 | I29: =IF(E29>=AVERAGE($E$6:$E$29),IF(G29>=$G$30,"نجم","حجم بلا ربحية"),IF(G29>=$G$30,"فرصة نمو","يحتاج مراجعة")) -> فرصة نمو | K29: 24 | L29: =INDEX($B$6:$B$29,MATCH($K29,$H$6:$H$29,0)) -> سجادة يوغا | M29: =INDEX($E$6:$E$29,MATCH($K29,$H$6:$H$29,0)) -> 21864 | N29: =IFERROR(M29/$E$30,0) -> 0.010233131 | O29: =SUM($N$6:N29) -> 1 | P29: =IF(O29-N29<0.8,"A",IF(O29-N29<0.95,"B","C")) -> C | Q29: =INDEX($G$6:$G$29,MATCH($K29,$H$6:$H$29,0)) -> 0.56092206
A30: الإجمالي | D30: =SUM(D6:D29) -> 4146 | E30: =SUM(E6:E29) -> 2136589.5 | F30: =SUM(F6:F29) -> 715514.5 | G30: =IFERROR(F30/E30,0) -> 0.33488628
K31: ملخص تصنيف ABC
K32: التصنيف | L32: عدد المنتجات | M32: الإيراد (ريال) | N32: الحصة
K33: A | L33: =COUNTIF($P$6:$P$29,K33) -> 16 | M33: =SUMIF($P$6:$P$29,K33,$M$6:$M$29) -> 1759576 | N33: =IFERROR(M33/$E$30,0) -> 0.82354425
K34: B | L34: =COUNTIF($P$6:$P$29,K34) -> 5 | M34: =SUMIF($P$6:$P$29,K34,$M$6:$M$29) -> 274141 | N34: =IFERROR(M34/$E$30,0) -> 0.12830775
K35: C | L35: =COUNTIF($P$6:$P$29,K35) -> 3 | M35: =SUMIF($P$6:$P$29,K35,$M$6:$M$29) -> 102872.5 | N35: =IFERROR(M35/$E$30,0) -> 0.048147995

Sheet تحليل العملاء
A1: تحليل العملاء وشرائح RFM
A2: ↩ الفهرس | B2: الحداثة (Recency) × التكرار (Frequency) × القيمة (Monetary) مع ترتيب أفضل العملاء
A3: تاريخ المرجع | B3: =MAX(d_Date)+1 -> 46296
A4: حدود الأرباع (تُحسب آلياً) | G4: أفضل 10 عملاء | M4: حسب نوع العميل
A5: المقياس | B5: الربع الأول (25%) | C5: الوسيط | D5: الربع الثالث (75%) | G5: # | H5: العميل | I5: الشريحة | J5: الإيراد (ريال) | K5: الحصة | M5: النوع | N5: عدد العملاء | O5: الإيراد (ريال)
A6: الحداثة (أيام) | B6: =QUARTILE($I$21:$I$220,1) -> 17.75 | C6: =QUARTILE($I$21:$I$220,2) -> 47 | D6: =QUARTILE($I$21:$I$220,3) -> 119.25 | G6: 1 | H6: =INDEX($B$21:$B$220,MATCH($G6,$O$21:$O$220,0)) -> خالد البلوي | I6: =INDEX($N$21:$N$220,MATCH($G6,$O$21:$O$220,0)) -> أبطال | J6: =INDEX($F$21:$F$220,MATCH($G6,$O$21:$O$220,0)) -> 147382 | K6: =IFERROR(J6/SUM(d_Rev),0) -> 0.068980026 | M6: أفراد | N6: =COUNTIF(c_Seg,$M6) -> 143 | O6: =SUMIF($C$21:$C$220,$M6,$F$21:$F$220) -> 1033844
A7: التكرار (طلبات) | B7: =QUARTILE($E$21:$E$220,1) -> 3 | C7: =QUARTILE($E$21:$E$220,2) -> 5 | D7: =QUARTILE($E$21:$E$220,3) -> 10 | G7: 2 | H7: =INDEX($B$21:$B$220,MATCH($G7,$O$21:$O$220,0)) -> خالد السبيعي | I7: =INDEX($N$21:$N$220,MATCH($G7,$O$21:$O$220,0)) -> أبطال | J7: =INDEX($F$21:$F$220,MATCH($G7,$O$21:$O$220,0)) -> 76998.5 | K7: =IFERROR(J7/SUM(d_Rev),0) -> 0.036038041 | M7: شركات صغيرة | N7: =COUNTIF(c_Seg,$M7) -> 45 | O7: =SUMIF($C$21:$C$220,$M7,$F$21:$F$220) -> 489296.5
A8: القيمة (ريال) | B8: =QUARTILE($F$21:$F$220,1) -> 2307 | C8: =QUARTILE($F$21:$F$220,2) -> 5908.25 | D8: =QUARTILE($F$21:$F$220,3) -> 13055 | G8: 3 | H8: =INDEX($B$21:$B$220,MATCH($G8,$O$21:$O$220,0)) -> أحمد الحربي | I8: =INDEX($N$21:$N$220,MATCH($G8,$O$21:$O$220,0)) -> أبطال | J8: =INDEX($F$21:$F$220,MATCH($G8,$O$21:$O$220,0)) -> 72854 | K8: =IFERROR(J8/SUM(d_Rev),0) -> 0.034098267 | M8: مؤسسات | N8: =COUNTIF(c_Seg,$M8) -> 12 | O8: =SUMIF($C$21:$C$220,$M8,$F$21:$F$220) -> 613449
G9: 4 | H9: =INDEX($B$21:$B$220,MATCH($G9,$O$21:$O$220,0)) -> نورة الشهري | I9: =INDEX($N$21:$N$220,MATCH($G9,$O$21:$O$220,0)) -> أبطال | J9: =INDEX($F$21:$F$220,MATCH($G9,$O$21:$O$220,0)) -> 68718 | K9: =IFERROR(J9/SUM(d_Rev),0) -> 0.032162472
A10: ملخص شرائح RFM | G10: 5 | H10: =INDEX($B$21:$B$220,MATCH($G10,$O$21:$O$220,0)) -> سعد التميمي | I10: =INDEX($N$21:$N$220,MATCH($G10,$O$21:$O$220,0)) -> أوفياء | J10: =INDEX($F$21:$F$220,MATCH($G10,$O$21:$O$220,0)) -> 63222 | K10: =IFERROR(J10/SUM(d_Rev),0) -> 0.029590148
A11: الشريحة | B11: عدد العملاء | C11: الإيراد (ريال) | D11: حصة الإيراد | E11: متوسط الإيراد/عميل | G11: 6 | H11: =INDEX($B$21:$B$220,MATCH($G11,$O$21:$O$220,0)) -> دانة العتيبي | I11: =INDEX($N$21:$N$220,MATCH($G11,$O$21:$O$220,0)) -> أبطال | J11: =INDEX($F$21:$F$220,MATCH($G11,$O$21:$O$220,0)) -> 56386.5 | K11: =IFERROR(J11/SUM(d_Rev),0) -> 0.026390891
A12: أبطال | B12: =COUNTIF($N$21:$N$220,$A12) -> 61 | C12: =SUMIF($N$21:$N$220,$A12,$F$21:$F$220) -> 1415872.5 | D12: =IFERROR(C12/$C$17,0) -> 0.66267877 | E12: =IFERROR(C12/B12,0) -> 23211.025 | G12: 7 | H12: =INDEX($B$21:$B$220,MATCH($G12,$O$21:$O$220,0)) -> أحمد القحطاني | I12: =INDEX($N$21:$N$220,MATCH($G12,$O$21:$O$220,0)) -> أبطال | J12: =INDEX($F$21:$F$220,MATCH($G12,$O$21:$O$220,0)) -> 47116.5 | K12: =IFERROR(J12/SUM(d_Rev),0) -> 0.0220522
A13: أوفياء | B13: =COUNTIF($N$21:$N$220,$A13) -> 42 | C13: =SUMIF($N$21:$N$220,$A13,$F$21:$F$220) -> 446213 | D13: =IFERROR(C13/$C$17,0) -> 0.20884358 | E13: =IFERROR(C13/B13,0) -> 10624.119 | G13: 8 | H13: =INDEX($B$21:$B$220,MATCH($G13,$O$21:$O$220,0)) -> عبدالله الحسيني | I13: =INDEX($N$21:$N$220,MATCH($G13,$O$21:$O$220,0)) -> أبطال | J13: =INDEX($F$21:$F$220,MATCH($G13,$O$21:$O$220,0)) -> 41249.5 | K13: =IFERROR(J13/SUM(d_Rev),0) -> 0.019306235
A14: واعدون | B14: =COUNTIF($N$21:$N$220,$A14) -> 42 | C14: =SUMIF($N$21:$N$220,$A14,$F$21:$F$220) -> 179904.5 | D14: =IFERROR(C14/$C$17,0) -> 0.084201715 | E14: =IFERROR(C14/B14,0) -> 4283.4405 | G14: 9 | H14: =INDEX($B$21:$B$220,MATCH($G14,$O$21:$O$220,0)) -> عبير القحطاني | I14: =INDEX($N$21:$N$220,MATCH($G14,$O$21:$O$220,0)) -> أبطال | J14: =INDEX($F$21:$F$220,MATCH($G14,$O$21:$O$220,0)) -> 37584 | K14: =IFERROR(J14/SUM(d_Rev),0) -> 0.017590651
A15: معرضون للفقد | B15: =COUNTIF($N$21:$N$220,$A15) -> 28 | C15: =SUMIF($N$21:$N$220,$A15,$F$21:$F$220) -> 74294 | D15: =IFERROR(C15/$C$17,0) -> 0.034772239 | E15: =IFERROR(C15/B15,0) -> 2653.3571 | G15: 10 | H15: =INDEX($B$21:$B$220,MATCH($G15,$O$21:$O$220,0)) -> طارق الشمري | I15: =INDEX($N$21:$N$220,MATCH($G15,$O$21:$O$220,0)) -> أوفياء | J15: =INDEX($F$21:$F$220,MATCH($G15,$O$21:$O$220,0)) -> 36980.5 | K15: =IFERROR(J15/SUM(d_Rev),0) -> 0.017308191
A16: نائمون | B16: =COUNTIF($N$21:$N$220,$A16) -> 27 | C16: =SUMIF($N$21:$N$220,$A16,$F$21:$F$220) -> 20305.5 | D16: =IFERROR(C16/$C$17,0) -> 0.0095036974 | E16: =IFERROR(C16/B16,0) -> 752.05556
A17: الإجمالي | B17: =SUM(B12:B16) -> 200 | C17: =SUM(C12:C16) -> 2136589.5 | D17: =SUM(D12:D16) -> 1 | E17: =IFERROR(C17/B17,0) -> 10682.948
A19: تفاصيل العملاء
A20: رقم العميل | B20: الاسم | C20: النوع | D20: المنطقة | E20: الطلبات | F20: الإيراد (ريال) | G20: الربح (ريال) | H20: آخر شراء | I20: الحداثة (يوم) | J20: R | K20: F | L20: M | M20: المجموع | N20: الشريحة | O20: ترتيب الإيراد
A21: C001 | B21: =INDEX(c_Name,MATCH($A21,c_ID,0)) -> محمد الدوسري | C21: =INDEX(c_Seg,MATCH($A21,c_ID,0)) -> أفراد | D21: =INDEX(c_Region,MATCH($A21,c_ID,0)) -> الشرقية | E21: =COUNTIFS(d_Cust,$A21,d_Status,"مكتمل") -> 1 | F21: =SUMIFS(d_Rev,d_Cust,$A21) -> 1710 | G21: =SUMIFS(d_Profit,d_Cust,$A21) -> 360 | H21: =IF(COUNTIF(d_Cust,$A21)=0,"",SUMPRODUCT(MAX((d_Cust=$A21)*d_Date))) -> 46295 | I21: =IF(H21="",$B$3-MIN(d_Date),$B$3-H21) -> 1 | J21: =IF(I21<=$B$6,4,IF(I21<=$C$6,3,IF(I21<=$D$6,2,1))) -> 4 | K21: =IF(E21>=$D$7,4,IF(E21>=$C$7,3,IF(E21>=$B$7,2,1))) -> 1 | L21: =IF(F21>=$D$8,4,IF(F21>=$C$8,3,IF(F21>=$B$8,2,1))) -> 1 | M21: =J21+K21+L21 -> 6 | N21: =IF(M21>=10,"أبطال",IF(M21>=8,"أوفياء",IF(M21>=6,"واعدون",IF(M21>=4,"معرضون للفقد","نائمون")))) -> واعدون | O21: =RANK(F21,$F$21:$F$220)+COUNTIF($F$21:F21,F21)-1 -> 164
A22: C002 | B22: =INDEX(c_Name,MATCH($A22,c_ID,0)) -> سلمان الخالدي | C22: =INDEX(c_Seg,MATCH($A22,c_ID,0)) -> شركات صغيرة | D22: =INDEX(c_Region,MATCH($A22,c_ID,0)) -> الشرقية | E22: =COUNTIFS(d_Cust,$A22,d_Status,"مكتمل") -> 6 | F22: =SUMIFS(d_Rev,d_Cust,$A22) -> 7279 | G22: =SUMIFS(d_Profit,d_Cust,$A22) -> 1764 | H22: =IF(COUNTIF(d_Cust,$A22)=0,"",SUMPRODUCT(MAX((d_Cust=$A22)*d_Date))) -> 46282 | I22: =IF(H22="",$B$3-MIN(d_Date),$B$3-H22) -> 14 | J22: =IF(I22<=$B$6,4,IF(I22<=$C$6,3,IF(I22<=$D$6,2,1))) -> 4 | K22: =IF(E22>=$D$7,4,IF(E22>=$C$7,3,IF(E22>=$B$7,2,1))) -> 3 | L22: =IF(F22>=$D$8,4,IF(F22>=$C$8,3,IF(F22>=$B$8,2,1))) -> 3 | M22: =J22+K22+L22 -> 10 | N22: =IF(M22>=10,"أبطال",IF(M22>=8,"أوفياء",IF(M22>=6,"واعدون",IF(M22>=4,"معرضون للفقد","نائمون")))) -> أبطال | O22: =RANK(F22,$F$21:$F$220)+COUNTIF($F$21:F22,F22)-1 -> 88
A23: C003 | B23: =INDEX(c_Name,MATCH($A23,c_ID,0)) -> هند الخالدي | C23: =INDEX(c_Seg,MATCH($A23,c_ID,0)) -> أفراد | D23: =INDEX(c_Region,MATCH($A23,c_ID,0)) -> الوسطى | E23: =COUNTIFS(d_Cust,$A23,d_Status,"مكتمل") -> 14 | F23: =SUMIFS(d_Rev,d_Cust,$A23) -> 13075.5 | G23: =SUMIFS(d_Profit,d_Cust,$A23) -> 4195.5 | H23: =IF(COUNTIF(d_Cust,$A23)=0,"",SUMPRODUCT(MAX((d_Cust=$A23)*d_Date))) -> 46251 | I23: =IF(H23="",$B$3-MIN(d_Date),$B$3-H23) -> 45 | J23: =IF(I23<=$B$6,4,IF(I23<=$C$6,3,IF(I23<=$D$6,2,1))) -> 3 | K23: =IF(E23>=$D$7,4,IF(E23>=$C$7,3,IF(E23>=$B$7,2,1))) -> 4 | L23: =IF(F23>=$D$8,4,IF(F23>=$C$8,3,IF(F23>=$B$8,2,1))) -> 4 | M23: =J23+K23+L23 -> 11 | N23: =IF(M23>=10,"أبطال",IF(M23>=8,"أوفياء",IF(M23>=6,"واعدون",IF(M23>=4,"معرضون للفقد","نائمون")))) -> أبطال | O23: =RANK(F23,$F$21:$F$220)+COUNTIF($F$21:F23,F23)-1 -> 49
